Workbook

Sheet Employees
A1: Employee Details - 2026
A5: Employee ID | B5: Employee Name | C5: Contact | D5: Department | E5: Designation | F5: Basic Salary | G5: Per Day Salary | H5: Per Hour Salary
A7: 1 | B7: Rajat Hela | C7: 9023270731 | D7: Production | E7: CNC Machine Operator | F7: 17000 | G7: =F7/26 -> 653.84615 | H7: =G7/11 -> 59.440559
A8: 2 | B8: Umesh Kumar | D8: Production | E8: CNC Machine Operator | F8: 18000 | G8: =F8/26 -> 692.30769 | H8: =G8/11 -> 62.937063
A9: 3 | B9: Ranjan Kumar | C9: 6206577886 | D9: Production | E9: CNC Machine Operator | F9: 21000 | G9: =F9/26 -> 807.69231 | H9: =G9/11 -> 73.426573

Sheet Advance Register
A1: Advance Register - 2026
A5: Date | B5: Employee ID | C5: Employee Name | D5: Amount | E5: Payment Mode | F5: Status | G5: Remarks
A7: 46037 | B7: 2 | C7: =VLOOKUP(B7,Employees!A:B,2,FALSE) -> Umesh Kumar | D7: 500 | E7: Cash | F7: Deducted | G7: -
A8: 46037 | B8: 1 | C8: =VLOOKUP(B8,Employees!A:B,2,FALSE) -> Rajat Hela | D8: 225 | E8: Cash | F8: Deducted | G8: Water Bottle (15)
A9: 46043 | B9: 1 | C9: =VLOOKUP(B9,Employees!A:B,2,FALSE) -> Rajat Hela | D9: 3000 | E9: Cash | F9: Deducted | G9: -
A10: 46043 | B10: 2 | C10: =VLOOKUP(B10,Employees!A:B,2,FALSE) -> Umesh Kumar | D10: 2000 | E10: Cash | F10: Deducted | G10: -
A11: 46055 | B11: 1 | C11: =VLOOKUP(B11,Employees!A:B,2,FALSE) -> Rajat Hela | D11: 1500 | E11: Cash | F11: Deducted | G11: -
A12: 46072 | B12: 2 | C12: =VLOOKUP(B12,Employees!A:B,2,FALSE) -> Umesh Kumar | D12: 12000 | E12: Cash | F12: Deducted | G12: -
A13: 46074 | B13: 1 | C13: =VLOOKUP(B13,Employees!A:B,2,FALSE) -> Rajat Hela | D13: 2000 | E13: Cash | F13: Deducted | G13: -
A14: 46084 | B14: 1 | C14: =VLOOKUP(B14,Employees!A:B,2,FALSE) -> Rajat Hela | D14: 1000 | E14: Cash | F14: Pending | G14: -
A15: 46103 | B15: 1 | C15: =VLOOKUP(B15,Employees!A:B,2,FALSE) -> Rajat Hela | D15: 3000 | E15: Cash | F15: Pending | G15: -
A16: 46109 | B16: 2 | C16: =VLOOKUP(B16,Employees!A:B,2,FALSE) -> Umesh Kumar | D16: 5000 | E16: Cash | F16: Pending | G16: -

Sheet Salary Register
A1: Salary Register - 2026
A3: Month | B3: Employee ID | C3: Employee Name | D3: Gross Salary | E3: Advance Deducted | F3: Other Deductions | G3: Net Salary Payable | H3: Payment Status | I3: Payment Date
A5: 46023 | B5: 1 | C5: =VLOOKUP(B5,Employees!A:B,2,FALSE) -> Rajat Hela | D5: =VLOOKUP(B5,'01-2026'!A:K,11,FALSE) -> 16274.825 | E5: =SUMIFS( 'Advance Register'!$D:$D, 'Advance Register'!$B:$B, B5, 'Advance Register'!$A:$A, ">="&DATE(2026,1,1), 'Advance Register'!$A:$A, "<="&EOMONTH(DATE(2026,1,1),0) ) -> 3225 | F5: 0 | G5: =MAX(0, D5 - E5 - F5) -> 13049.825 | H5: Paid - Cash | I5: 46063
A6: 46023 | B6: 2 | C6: =VLOOKUP(B6,Employees!A:B,2,FALSE) -> Umesh Kumar | D6: =VLOOKUP(B6,'01-2026'!A:K,11,FALSE) -> 14809.091 | E6: =SUMIFS( 'Advance Register'!$D:$D, 'Advance Register'!$B:$B, B6, 'Advance Register'!$A:$A, ">="&DATE(2026,1,1), 'Advance Register'!$A:$A, "<="&EOMONTH(DATE(2026,1,1),0) ) -> 2500 | F6: 0 | G6: =MAX(0, D6 - E6 - F6) -> 12309.091 | H6: Paid - Cash | I6: 46063
A7: 46054 | B7: 1 | C7: =VLOOKUP(B7,Employees!A:B,2,FALSE) -> Rajat Hela | D7: =VLOOKUP(B7,'02-2026'!A:K,11,FALSE) -> 16423.427 | E7: =SUMIFS( 'Advance Register'!$D:$D, 'Advance Register'!$B:$B, B7, 'Advance Register'!$A:$A, ">="&DATE(2026,2,1), 'Advance Register'!$A:$A, "<="&EOMONTH(DATE(2026,2,1),0) ) -> 3500 | F7: 0 | G7: =MAX(0, D7 - E7 - F7) -> 12923.427 | H7: Paid - Cash | I7: 46089
A8: 46054 | B8: 2 | C8: =VLOOKUP(B8,Employees!A:B,2,FALSE) -> Umesh Kumar | D8: =VLOOKUP(B8,'02-2026'!A:K,11,FALSE) -> 18081.818 | E8: =SUMIFS( 'Advance Register'!$D:$D, 'Advance Register'!$B:$B, B8, 'Advance Register'!$A:$A, ">="&DATE(2026,2,1), 'Advance Register'!$A:$A, "<="&EOMONTH(DATE(2026,2,1),0) ) -> 12000 | F8: 0 | G8: =MAX(0, D8 - E8 - F8) -> 6081.8182 | H8: Paid - Cash | I8: 46089
A9: 46082 | B9: 1 | C9: =VLOOKUP(B9,Employees!A:B,2,FALSE) -> Rajat Hela | D9: =VLOOKUP(B9,'03-2026'!A:K,11,FALSE) -> 17552.797 | E9: =SUMIFS( 'Advance Register'!$D:$D, 'Advance Register'!$B:$B, B9, 'Advance Register'!$A:$A, ">="&DATE(2026,3,1), 'Advance Register'!$A:$A, "<="&EOMONTH(DATE(2026,3,1),0) ) -> 4000 | F9: 0 | G9: =MAX(0, D9 - E9 - F9) -> 13552.797 | H9: Paid - Cash | I9: 46238
A10: 46082 | B10: 2 | C10: =VLOOKUP(B10,Employees!A:B,2,FALSE) -> Umesh Kumar | D10: =VLOOKUP(B10,'03-2026'!A:K,11,FALSE) -> 17074.825 | E10: =SUMIFS( 'Advance Register'!$D:$D, 'Advance Register'!$B:$B, B10, 'Advance Register'!$A:$A, ">="&DATE(2026,3,1), 'Advance Register'!$A:$A, "<="&EOMONTH(DATE(2026,3,1),0) ) -> 5000 | F10: 0 | G10: =MAX(0, D10 - E10 - F10) -> 12074.825 | H10: Pending
A11: 46113 | B11: 1 | C11: =VLOOKUP(B11,Employees!A:B,2,FALSE) -> Rajat Hela | D11: =VLOOKUP(B11,'04-2026'!A:K,11,FALSE) -> 15418.881 | E11: =SUMIFS( 'Advance Register'!$D:$D, 'Advance Register'!$B:$B, B11, 'Advance Register'!$A:$A, ">="&DATE(2026,3,1), 'Advance Register'!$A:$A, "<="&EOMONTH(DATE(2026,3,1),0) ) -> 4000 | G11: =MAX(0, D11 - E11 - F11) -> 11418.881

Sheet 01-2026
A1: 46023
A5: Emp ID | B5: Employee Name | C5: Contact | D5: Department | E5: Designation | F5: Basic Salary | G5: Per Day Salary | H5: Per Hour Salary | I5: Total Hours | J5: Total OT (hrs) | K5: Salary Earned
A6: 1 | B6: =VLOOKUP(A6,Employees!A:B,2,FALSE) -> Rajat Hela | C6: =VLOOKUP(A6,Employees!A:C,3,FALSE) -> 9023270731 | D6: =VLOOKUP(A6,Employees!A:D,4,FALSE) -> Production | E6: =VLOOKUP(A6,Employees!A:E,5,FALSE) -> CNC Machine Operator | F6: =VLOOKUP(A6,Employees!A:F,6,FALSE) -> 17000 | G6: =VLOOKUP(A6,Employees!A:G,7,FALSE) -> 653.84615 | H6: =VLOOKUP(A6,Employees!A:H,8,FALSE) -> 59.440559 | I6: =SUMIFS('01-2026'!$L$10:$L$308, '01-2026'!$B$10:$B$308, $A6) -> 267.8 | J6: =SUMIFS('01-2026'!$M$10:$M$308, '01-2026'!$B$10:$B$308, $A6) -> 6 | K6: =('01-2026'!$I6+'01-2026'!$J6)*'01-2026'!$H6 -> 16274.825
A7: 2 | B7: =VLOOKUP(A7,Employees!A:B,2,FALSE) -> Umesh Kumar | C7: =VLOOKUP(A7,Employees!A:C,3,FALSE) | D7: =VLOOKUP(A7,Employees!A:D,4,FALSE) -> Production | E7: =VLOOKUP(A7,Employees!A:E,5,FALSE) -> CNC Machine Operator | F7: =VLOOKUP(A7,Employees!A:F,6,FALSE) -> 18000 | G7: =VLOOKUP(A7,Employees!A:G,7,FALSE) -> 692.30769 | H7: =VLOOKUP(A7,Employees!A:H,8,FALSE) -> 62.937063 | I7: =SUMIFS('01-2026'!$L$10:$L$308, '01-2026'!$B$10:$B$308, $A7) -> 217.3 | J7: =SUMIFS('01-2026'!$M$10:$M$308, '01-2026'!$B$10:$B$308, $A7) -> 18 | K7: =('01-2026'!$I7+'01-2026'!$J7)*'01-2026'!$H7 -> 14809.091
A9: Date | B9: Employee ID | C9: Employee Name | D9: Check-In | E9: Break Start | F9: Break End | G9: Check-Out | H9: Total Break (hrs) | I9: Total Working (hrs) | J9: Net Working (hrs) | K9: Over Time (hrs) | L9: NW (For Calc) | M9: Ot (For Calc)
L10: =IF(J10="","", IFERROR( HOUR(J10)+MINUTE(J10)/100, HOUR(TIMEVALUE(SUBSTITUTE(J10,CHAR(160),""))) +MINUTE(TIMEVALUE(SUBSTITUTE(J10,CHAR(160),"")))/100 ) ) | M10: =IF(K10="","", IFERROR( HOUR(K10)+MINUTE(K10)/100, HOUR(TIMEVALUE(SUBSTITUTE(K10,CHAR(160),""))) +MINUTE(TIMEVALUE(SUBSTITUTE(K10,CHAR(160),"")))/100 ) )
A11: 46023 | B11: 1 | C11: =VLOOKUP(B11,Employees!A:B,2,FALSE) -> Rajat Hela | D11: 0.33333333 | E11: 0.54166667 | F11: 0.58333333 | G11: 0.69444444 | H11: =F11 - E11 -> 0.041666667 | I11: =G11 - D11 -> 0.36111111 | J11: =I11 - H11 -> 0.31944444 | K11: =MAX( 0, MOD( IFERROR( J11, TIMEVALUE(SUBSTITUTE(J11,CHAR(160),"")) ), 1 ) - TIME(11,0,0) ) -> 0 | L11: =IF(J11="","", IFERROR( HOUR(MIN(MOD(J11,1), TIME(11,0,0))) + MINUTE(MIN(MOD(J11,1), TIME(11,0,0)))/100, HOUR(MIN(MOD(TIMEVALUE(SUBSTITUTE(J11,CHAR(160),"")),1), TIME(11,0,0))) + MINUTE(MIN(MOD(TIMEVALUE(SUBSTITUTE(J11,CHAR(160),"")),1), TIME(11,0,0)))/100 ) ) -> 7.4 | M11: =IF(K11="","", IFERROR( HOUR(K11)+MINUTE(K11)/100, HOUR(TIMEVALUE(SUBSTITUTE(K11,CHAR(160),""))) +MINUTE(TIMEVALUE(SUBSTITUTE(K11,CHAR(160),"")))/100 ) ) -> 0
A12: 46024 | B12: 1 | C12: =VLOOKUP(B12,Employees!A:B,2,FALSE) -> Rajat Hela | D12: 0.33333333 | E12: 0.5625 | F12: 0.60416667 | G12: 0.83333333 | H12: =F12 - E12 -> 0.041666667 | I12: =G12 - D12 -> 0.5 | J12: =I12 - H12 -> 0.45833333 | K12: =MAX( 0, MOD( IFERROR( J12, TIMEVALUE(SUBSTITUTE(J12,CHAR(160),"")) ), 1 ) - TIME(11,0,0) ) -> 0 | L12: =IF(J12="","", IFERROR( HOUR(MIN(MOD(J12,1), TIME(11,0,0))) + MINUTE(MIN(MOD(J12,1), TIME(11,0,0)))/100, HOUR(MIN(MOD(TIMEVALUE(SUBSTITUTE(J12,CHAR(160),"")),1), TIME(11,0,0))) + MINUTE(MIN(MOD(TIMEVALUE(SUBSTITUTE(J12,CHAR(160),"")),1), TIME(11,0,0)))/100 ) ) -> 11 | M12: =IF(K12="","", IFERROR( HOUR(K12)+MINUTE(K12)/100, HOUR(TIMEVALUE(SUBSTITUTE(K12,CHAR(160),""))) +MINUTE(TIMEVALUE(SUBSTITUTE(K12,CHAR(160),"")))/100 ) ) -> 0
A13: 46025 | B13: 1 | C13: =VLOOKUP(B13,Employees!A:B,2,FALSE) -> Rajat Hela | D13: 0.33333333 | E13: 0.54166667 | F13: 0.58333333 | G13: 0.83333333 | H13: =F13 - E13 -> 0.041666667 | I13: =G13 - D13 -> 0.5 | J13: =I13 - H13 -> 0.45833333 | K13: =MAX( 0, MOD( IFERROR( J13, TIMEVALUE(SUBSTITUTE(J13,CHAR(160),"")) ), 1 ) - TIME(11,0,0) ) -> 0 | L13: =IF(J13="","", IFERROR( HOUR(MIN(MOD(J13,1), TIME(11,0,0))) + MINUTE(MIN(MOD(J13,1), TIME(11,0,0)))/100, HOUR(MIN(MOD(TIMEVALUE(SUBSTITUTE(J13,CHAR(160),"")),1), TIME(11,0,0))) + MINUTE(MIN(MOD(TIMEVALUE(SUBSTITUTE(J13,CHAR(160),"")),1), TIME(11,0,0)))/100 ) ) -> 11 | M13: =IF(K13="","", IFERROR( HOUR(K13)+MINUTE(K13)/100, HOUR(TIMEVALUE(SUBSTITUTE(K13,CHAR(160),""))) +MINUTE(TIMEVALUE(SUBSTITUTE(K13,CHAR(160),"")))/100 ) ) -> 0
A14: 46026 | B14: 1 | C14: =VLOOKUP(B14,Employees!A:B,2,FALSE) -> Rajat Hela | D14: 0.33333333 | E14: 0.5 | F14: 0.54166667 | G14: 0.6875 | H14: =F14 - E14 -> 0.041666667 | I14: =G14 - D14 -> 0.35416667 | J14: =I14 - H14 -> 0.3125 | K14: =MAX( 0, MOD( IFERROR( J14, TIMEVALUE(SUBSTITUTE(J14,CHAR(160),"")) ), 1 ) - TIME(11,0,0) ) -> 0 | L14: =IF(J14="","", IFERROR( HOUR(MIN(MOD(J14,1), TIME(11,0,0))) + MINUTE(MIN(MOD(J14,1), TIME(11,0,0)))/100, HOUR(MIN(MOD(TIMEVALUE(SUBSTITUTE(J14,CHAR(160),"")),1), TIME(11,0,0))) + MINUTE(MIN(MOD(TIMEVALUE(SUBSTITUTE(J14,CHAR(160),"")),1), TIME(11,0,0)))/100 ) ) -> 7.3 | M14: =IF(K14="","", IFERROR( HOUR(K14)+MINUTE(K14)/100, HOUR(TIMEVALUE(SUBSTITUTE(K14,CHAR(160),""))) +MINUTE(TIMEVALUE(SUBSTITUTE(K14,CHAR(160),"")))/100 ) ) -> 0
B15: 1 | C15: =VLOOKUP(B15,Employees!A:B,2,FALSE) -> Rajat Hela | D15: 0.875 | G15: 1.0208333 | H15: =F15 - E15 -> 0 | I15: =G15 - D15 -> 0.14583333 | J15: =I15 - H15 -> 0.14583333 | K15: =MAX( 0, MOD( IFERROR( J15, TIMEVALUE(SUBSTITUTE(J15,CHAR(160),"")) ), 1 ) - TIME(11,0,0) ) -> 0 | L15: =IF(J15="","", IFERROR( HOUR(MIN(MOD(J15,1), TIME(11,0,0))) + MINUTE(MIN(MOD(J15,1), TIME(11,0,0)))/100, HOUR(MIN(MOD(TIMEVALUE(SUBSTITUTE(J15,CHAR(160),"")),1), TIME(11,0,0))) + MINUTE(MIN(MOD(TIMEVALUE(SUBSTITUTE(J15,CHAR(160),"")),1), TIME(11,0,0)))/100 ) ) -> 3.3 | M15: =IF(K15="","", IFERROR( HOUR(K15)+MINUTE(K15)/100, HOUR(TIMEVALUE(SUBSTITUTE(K15,CHAR(160),""))) +MINUTE(TIMEVALUE(SUBSTITUTE(K15,CHAR(160),"")))/100 ) ) -> 0
A16: 46027 | B16: 1 | C16: =VLOOKUP(B16,Employees!A:B,2,FALSE) -> Rajat Hela | D16: 0.33333333 | E16: 0.54166667 | F16: 0.58333333 | G16: 0.73611111 | H16: =F16 - E16 -> 0.041666667 | I16: =G16 - D16 -> 0.40277778 | J16: =I16 - H16 -> 0.36111111 | K16: =MAX( 0, MOD( IFERROR( J16, TIMEVALUE(SUBSTITUTE(J16,CHAR(160),"")) ), 1 ) - TIME(11,0,0) ) -> 0 | L16: =IF(J16="","", IFERROR( HOUR(MIN(MOD(J16,1), TIME(11,0,0))) + MINUTE(MIN(MOD(J16,1), TIME(11,0,0)))/100, HOUR(MIN(MOD(TIMEVALUE(SUBSTITUTE(J16,CHAR(160),"")),1), TIME(11,0,0))) + MINUTE(MIN(MOD(TIMEVALUE(SUBSTITUTE(J16,CHAR(160),"")),1), TIME(11,0,0)))/100 ) ) -> 8.4 | M16: =IF(K16="","", IFERROR( HOUR(K16)+MINUTE(K16)/100, HOUR(TIMEVALUE(SUBSTITUTE(K16,CHAR(160),""))) +MINUTE(TIMEVALUE(SUBSTITUTE(K16,CHAR(160),"")))/100 ) ) -> 0
A17: 46028 | B17: 1 | C17: =VLOOKUP(B17,Employees!A:B,2,FALSE) -> Rajat Hela | D17: 0.33333333 | E17: 0.54166667 | F17: 0.58333333 | G17: 0.83333333 | H17: =F17 - E17 -> 0.041666667 | I17: =G17 - D17 -> 0.5 | J17: =I17 - H17 -> 0.45833333 | K17: =MAX( 0, MOD( IFERROR( J17, TIMEVALUE(SUBSTITUTE(J17,CHAR(160),"")) ), 1 ) - TIME(11,0,0) ) -> 0 | L17: =IF(J17="","", IFERROR( HOUR(MIN(MOD(J17,1), TIME(11,0,0))) + MINUTE(MIN(MOD(J17,1), TIME(11,0,0)))/100, HOUR(MIN(MOD(TIMEVALUE(SUBSTITUTE(J17,CHAR(160),"")),1), TIME(11,0,0))) + MINUTE(MIN(MOD(TIMEVALUE(SUBSTITUTE(J17,CHAR(160),"")),1), TIME(11,0,0)))/100 ) ) -> 11 | M17: =IF(K17="","", IFERROR( HOUR(K17)+MINUTE(K17)/100, HOUR(TIMEVALUE(SUBSTITUTE(K17,CHAR(160),""))) +MINUTE(TIMEVALUE(SUBSTITUTE(K17,CHAR(160),"")))/100 ) ) -> 0
B18: 1 | C18: =VLOOKUP(B18,Employees!A:B,2,FALSE) -> Rajat Hela | D18: 0.875 | G18: 0.33333333 | H18: =F18 - E18 -> 0 | I18: =G18 - D18 -> -0.54166667 | J18: =I18 - H18 -> -0.54166667 | K18: =MAX( 0, MOD( IFERROR( J18, TIMEVALUE(SUBSTITUTE(J18,CHAR(160),"")) ), 1 ) - TIME(11,0,0) ) -> 0 | L18: =IF(J18="","", IFERROR( HOUR(MIN(MOD(J18,1), TIME(11,0,0))) + MINUTE(MIN(MOD(J18,1), TIME(11,0,0)))/100, HOUR(MIN(MOD(TIMEVALUE(SUBSTITUTE(J18,CHAR(160),"")),1), TIME(11,0,0))) + MINUTE(MIN(MOD(TIMEVALUE(SUBSTITUTE(J18,CHAR(160),"")),1), TIME(11,0,0)))/100 ) ) -> 11 | M18: =IF(K18="","", IFERROR( HOUR(K18)+MINUTE(K18)/100, HOUR(TIMEVALUE(SUBSTITUTE(K18,CHAR(160),""))) +MINUTE(TIMEVALUE(SUBSTITUTE(K18,CHAR(160),"")))/100 ) ) -> 0
A19: 46029 | G19: Wednesday | L19: =IF(J19="","", IFERROR( HOUR(MIN(MOD(J19,1), TIME(11,0,0))) + MINUTE(MIN(MOD(J19,1), TIME(11,0,0)))/100, HOUR(MIN(MOD(TIMEVALUE(SUBSTITUTE(J19,CHAR(160),"")),1), TIME(11,0,0))) + MINUTE(MIN(MOD(TIMEVALUE(SUBSTITUTE(J19,CHAR(160),"")),1), TIME(11,0,0)))/100 ) ) | M19: =IF(K19="","", IFERROR( HOUR(K19)+MINUTE(K19)/100, HOUR(TIMEVALUE(SUBSTITUTE(K19,CHAR(160),""))) +MINUTE(TIMEVALUE(SUBSTITUTE(K19,CHAR(160),"")))/100 ) )
A20: 46030 | G20: Setting | L20: =IF(J20="","", IFERROR( HOUR(MIN(MOD(J20,1), TIME(11,0,0))) + MINUTE(MIN(MOD(J20,1), TIME(11,0,0)))/100, HOUR(MIN(MOD(TIMEVALUE(SUBSTITUTE(J20,CHAR(160),"")),1), TIME(11,0,0))) + MINUTE(MIN(MOD(TIMEVALUE(SUBSTITUTE(J20,CHAR(160),"")),1), TIME(11,0,0)))/100 ) ) | M20: =IF(K20="","", IFERROR( HOUR(K20)+MINUTE(K20)/100, HOUR(TIMEVALUE(SUBSTITUTE(K20,CHAR(160),""))) +MINUTE(TIMEVALUE(SUBSTITUTE(K20,CHAR(160),"")))/100 ) )
A21: 46031 | B21: 1 | C21: =VLOOKUP(B21,Employees!A:B,2,FALSE) -> Rajat Hela | D21: 0.33333333 | E21: 0.54166667 | F21: 0.58333333 | G21: 0.83333333 | H21: =F21 - E21 -> 0.041666667 | I21: =G21 - D21 -> 0.5 | J21: =I21 - H21 -> 0.45833333 | K21: =MAX( 0, MOD( IFERROR( J21, TIMEVALUE(SUBSTITUTE(J21,CHAR(160),"")) ), 1 ) - TIME(11,0,0) ) -> 0 | L21: =IF(J21="","", IFERROR( HOUR(MIN(MOD(J21,1), TIME(11,0,0))) + MINUTE(MIN(MOD(J21,1), TIME(11,0,0)))/100, HOUR(MIN(MOD(TIMEVALUE(SUBSTITUTE(J21,CHAR(160),"")),1), TIME(11,0,0))) + MINUTE(MIN(MOD(TIMEVALUE(SUBSTITUTE(J21,CHAR(160),"")),1), TIME(11,0,0)))/100 ) ) -> 11 | M21: =IF(K21="","", IFERROR( HOUR(K21)+MINUTE(K21)/100, HOUR(TIMEVALUE(SUBSTITUTE(K21,CHAR(160),""))) +MINUTE(TIMEVALUE(SUBSTITUTE(K21,CHAR(160),"")))/100 ) ) -> 0
B22: 1 | C22: =VLOOKUP(B22,Employees!A:B,2,FALSE) -> Rajat Hela | D22: 0.875 | G22: 0.041666667 | H22: =F22 - E22 -> 0 | I22: =G22 - D22 -> -0.83333333 | J22: =I22 - H22 -> -0.83333333 | K22: =MAX( 0, MOD( IFERROR( J22, TIMEVALUE(SUBSTITUTE(J22,CHAR(160),"")) ), 1 ) - TIME(11,0,0) ) -> 0 | L22: =IF(J22="","", IFERROR( HOUR(MIN(MOD(J22,1), TIME(11,0,0))) + MINUTE(MIN(MOD(J22,1), TIME(11,0,0)))/100, HOUR(MIN(MOD(TIMEVALUE(SUBSTITUTE(J22,CHAR(160),"")),1), TIME(11,0,0))) + MINUTE(MIN(MOD(TIMEVALUE(SUBSTITUTE(J22,CHAR(160),"")),1), TIME(11,0,0)))/100 ) ) -> 4 | M22: =IF(K22="","", IFERROR( HOUR(K22)+MINUTE(K22)/100, HOUR(TIMEVALUE(SUBSTITUTE(K22,CHAR(160),""))) +MINUTE(TIMEVALUE(SUBSTITUTE(K22,CHAR(160),"")))/100 ) ) -> 0
A23: 46032 | B23: 1 | C23: =VLOOKUP(B23,Employees!A:B,2,FALSE) -> Rajat Hela | D23: 0.33333333 | E23: 0.54166667 | F23: 0.58333333 | G23: 0.83333333 | H23: =F23 - E23 -> 0.041666667 | I23: =G23 - D23 -> 0.5 | J23: =I23 - H23 -> 0.45833333 | K23: =MAX( 0, MOD( IFERROR( J23, TIMEVALUE(SUBSTITUTE(J23,CHAR(160),"")) ), 1 ) - TIME(11,0,0) ) -> 0 | L23: =IF(J23="","", IFERROR( HOUR(MIN(MOD(J23,1), TIME(11,0,0))) + MINUTE(MIN(MOD(J23,1), TIME(11,0,0)))/100, HOUR(MIN(MOD(TIMEVALUE(SUBSTITUTE(J23,CHAR(160),"")),1), TIME(11,0,0))) + MINUTE(MIN(MOD(TIMEVALUE(SUBSTITUTE(J23,CHAR(160),"")),1), TIME(11,0,0)))/100 ) ) -> 11 | M23: =IF(K23="","", IFERROR( HOUR(K23)+MINUTE(K23)/100, HOUR(TIMEVALUE(SUBSTITUTE(K23,CHAR(160),""))) +MINUTE(TIMEVALUE(SUBSTITUTE(K23,CHAR(160),"")))/100 ) ) -> 0
B24: 1 | C24: =VLOOKUP(B24,Employees!A:B,2,FALSE) -> Rajat Hela | D24: 0.875 | G24: 1 | H24: =F24 - E24 -> 0 | I24: =G24 - D24 -> 0.125 | J24: =I24 - H24 -> 0.125 | K24: =MAX( 0, MOD( IFERROR( J24, TIMEVALUE(SUBSTITUTE(J24,CHAR(160),"")) ), 1 ) - TIME(11,0,0) ) -> 0 | L24: =IF(J24="","", IFERROR( HOUR(MIN(MOD(J24,1), TIME(11,0,0))) + MINUTE(MIN(MOD(J24,1), TIME(11,0,0)))/100, HOUR(MIN(MOD(TIMEVALUE(SUBSTITUTE(J24,CHAR(160),"")),1), TIME(11,0,0))) + MINUTE(MIN(MOD(TIMEVALUE(SUBSTITUTE(J24,CHAR(160),"")),1), TIME(11,0,0)))/100 ) ) -> 3 | M24: =IF(K24="","", IFERROR( HOUR(K24)+MINUTE(K24)/100, HOUR(TIMEVALUE(SUBSTITUTE(K24,CHAR(160),""))) +MINUTE(TIMEVALUE(SUBSTITUTE(K24,CHAR(160),"")))/100 ) ) -> 0
A25: 46033 | B25: 1 | C25: =VLOOKUP(B25,Employees!A:B,2,FALSE) -> Rajat Hela | D25: 0.33333333 | E25: 0.56944444 | F25: 0.61111111 | G25: 0.61111111 | H25: =F25 - E25 -> 0.041666667 | I25: =G25 - D25 -> 0.27777778 | J25: =I25 - H25 -> 0.23611111 | K25: =MAX( 0, MOD( IFERROR( J25, TIMEVALUE(SUBSTITUTE(J25,CHAR(160),"")) ), 1 ) - TIME(11,0,0) ) -> 0 | L25: =IF(J25="","", IFERROR( HOUR(MIN(MOD(J25,1), TIME(11,0,0))) + MINUTE(MIN(MOD(J25,1), TIME(11,0,0)))/100, HOUR(MIN(MOD(TIMEVALUE(SUBSTITUTE(J25,CHAR(160),"")),1), TIME(11,0,0))) + MINUTE(MIN(MOD(TIMEVALUE(SUBSTITUTE(J25,CHAR(160),"")),1), TIME(11,0,0)))/100 ) ) -> 5.4 | M25: =IF(K25="","", IFERROR( HOUR(K25)+MINUTE(K25)/100, HOUR(TIMEVALUE(SUBSTITUTE(K25,CHAR(160),""))) +MINUTE(TIMEVALUE(SUBSTITUTE(K25,CHAR(160),"")))/100 ) ) -> 0
B26: 2 | C26: =VLOOKUP(B26,Employees!A:B,2,FALSE) -> Umesh Kumar | D26: 0.83333333 | G26: 0.33333333 | H26: =F26 - E26 -> 0 | I26: =G26 - D26 -> -0.5 | J26: =I26 - H26 -> -0.5 | K26: =MAX( 0, MOD( IFERROR( J26, TIMEVALUE(SUBSTITUTE(J26,CHAR(160),"")) ), 1 ) - TIME(11,0,0) ) -> 0.041666667 | L26: =IF(J26="","", IFERROR( HOUR(MIN(MOD(J26,1), TIME(11,0,0))) + MINUTE(MIN(MOD(J26,1), TIME(11,0,0)))/100, HOUR(MIN(MOD(TIMEVALUE(SUBSTITUTE(J26,CHAR(160),"")),1), TIME(11,0,0))) + MINUTE(MIN(MOD(TIMEVALUE(SUBSTITUTE(J26,CHAR(160),"")),1), TIME(11,0,0)))/100 ) ) -> 11
A27: 46034 | B27: 1 | C27: =VLOOKUP(B27,Employees!A:B,2,FALSE) -> Rajat Hela | D27: 0.33333333 | E27: 0.54166667 | F27: 0.58333333 | G27: 0.83333333 | H27: =F27 - E27 -> 0.041666667 | I27: =G27 - D27 -> 0.5 | J27: =I27 - H27 -> 0.45833333 | K27: =MAX( 0, MOD( IFERROR( J27, TIMEVALUE(SUBSTITUTE(J27,CHAR(160),"")) ), 1 ) - TIME(11,0,0) ) -> 0 | L27: =IF(J27="","", IFERROR( HOUR(MIN(MOD(J27,1), TIME(11,0,0))) + MINUTE(MIN(MOD(J27,1), TIME(11,0,0)))/100, HOUR(MIN(MOD(TIMEVALUE(SUBSTITUTE(J27,CHAR(160),"")),1), TIME(11,0,0))) + MINUTE(MIN(MOD(TIMEVALUE(SUBSTITUTE(J27,CHAR(160),"")),1), TIME(11,0,0)))/100 ) ) -> 11 | M27: =IF(K27="","", IFERROR( HOUR(K27)+MINUTE(K27)/100, HOUR(TIMEVALUE(SUBSTITUTE(K27,CHAR(160),""))) +MINUTE(TIMEVALUE(SUBSTITUTE(K27,CHAR(160),"")))/100 ) ) -> 0
B28: 2 | C28: =VLOOKUP(B28,Employees!A:B,2,FALSE) -> Umesh Kumar | D28: 0.83333333 | G28: 0.33333333 | H28: =F28 - E28 -> 0 | I28: =G28 - D28 -> -0.5 | J28: =I28 - H28 -> -0.5 | K28: =MAX( 0, MOD( IFERROR( J28, TIMEVALUE(SUBSTITUTE(J28,CHAR(160),"")) ), 1 ) - TIME(11,0,0) ) -> 0.041666667 | L28: =IF(J28="","", IFERROR( HOUR(MIN(MOD(J28,1), TIME(11,0,0))) + MINUTE(MIN(MOD(J28,1), TIME(11,0,0)))/100, HOUR(MIN(MOD(TIMEVALUE(SUBSTITUTE(J28,CHAR(160),"")),1), TIME(11,0,0))) + MINUTE(MIN(MOD(TIMEVALUE(SUBSTITUTE(J28,CHAR(160),"")),1), TIME(11,0,0)))/100 ) ) -> 11 | M28: =IF(K28="","", IFERROR( HOUR(K28)+MINUTE(K28)/100, HOUR(TIMEVALUE(SUBSTITUTE(K28,CHAR(160),""))) +MINUTE(TIMEVALUE(SUBSTITUTE(K28,CHAR(160),"")))/100 ) ) -> 1
A29: 46035 | B29: 1 | C29: =VLOOKUP(B29,Employees!A:B,2,FALSE) -> Rajat Hela | D29: 0.33333333 | E29: 0.52083333 | F29: 0.5625 | G29: 0.83333333 | H29: =F29 - E29 -> 0.041666667 | I29: =G29 - D29 -> 0.5 | J29: =I29 - H29 -> 0.45833333 | K29: =MAX( 0, MOD( IFERROR( J29, TIMEVALUE(SUBSTITUTE(J29,CHAR(160),"")) ), 1 ) - TIME(11,0,0) ) -> 0 | L29: =IF(J29="","", IFERROR( HOUR(MIN(MOD(J29,1), TIME(11,0,0))) + MINUTE(MIN(MOD(J29,1), TIME(11,0,0)))/100, HOUR(MIN(MOD(TIMEVALUE(SUBSTITUTE(J29,CHAR(160),"")),1), TIME(11,0,0))) + MINUTE(MIN(MOD(TIMEVALUE(SUBSTITUTE(J29,CHAR(160),"")),1), TIME(11,0,0)))/100 ) ) -> 11 | M29: =IF(K29="","", IFERROR( HOUR(K29)+MINUTE(K29)/100, HOUR(TIMEVALUE(SUBSTITUTE(K29,CHAR(160),""))) +MINUTE(TIMEVALUE(SUBSTITUTE(K29,CHAR(160),"")))/100 ) ) -> 0
B30: 2 | C30: =VLOOKUP(B30,Employees!A:B,2,FALSE) -> Umesh Kumar | D30: 0.83333333 | G30: 0.33333333 | H30: =F30 - E30 -> 0 | I30: =G30 - D30 -> -0.5 | J30: =I30 - H30 -> -0.5 | K30: =MAX( 0, MOD( IFERROR( J30, TIMEVALUE(SUBSTITUTE(J30,CHAR(160),"")) ), 1 ) - TIME(11,0,0) ) -> 0.041666667 | L30: =IF(J30="","", IFERROR( HOUR(MIN(MOD(J30,1), TIME(11,0,0))) + MINUTE(MIN(MOD(J30,1), TIME(11,0,0)))/100, HOUR(MIN(MOD(TIMEVALUE(SUBSTITUTE(J30,CHAR(160),"")),1), TIME(11,0,0))) + MINUTE(MIN(MOD(TIMEVALUE(SUBSTITUTE(J30,CHAR(160),"")),1), TIME(11,0,0)))/100 ) ) -> 11 | M30: =IF(K30="","", IFERROR( HOUR(K30)+MINUTE(K30)/100, HOUR(TIMEVALUE(SUBSTITUTE(K30,CHAR(160),""))) +MINUTE(TIMEVALUE(SUBSTITUTE(K30,CHAR(160),"")))/100 ) ) -> 1
A31: 46036 | G31: Wednesday | L31: =IF(J31="","", IFERROR( HOUR(MIN(MOD(J31,1), TIME(11,0,0))) + MINUTE(MIN(MOD(J31,1), TIME(11,0,0)))/100, HOUR(MIN(MOD(TIMEVALUE(SUBSTITUTE(J31,CHAR(160),"")),1), TIME(11,0,0))) + MINUTE(MIN(MOD(TIMEVALUE(SUBSTITUTE(J31,CHAR(160),"")),1), TIME(11,0,0)))/100 ) ) | M31: =IF(K31="","", IFERROR( HOUR(K31)+MINUTE(K31)/100, HOUR(TIMEVALUE(SUBSTITUTE(K31,CHAR(160),""))) +MINUTE(TIMEVALUE(SUBSTITUTE(K31,CHAR(160),"")))/100 ) )
A32: 46037 | B32: 2 | C32: =VLOOKUP(B32,Employees!A:B,2,FALSE) -> Umesh Kumar | D32: 0.33333333 | E32: 0.54166667 | F32: 0.58333333 | G32: 0.91666667 | H32: =F32 - E32 -> 0.041666667 | I32: =G32 - D32 -> 0.58333333 | J32: =I32 - H32 -> 0.54166667 | K32: =MAX( 0, MOD( IFERROR( J32, TIMEVALUE(SUBSTITUTE(J32,CHAR(160),"")) ), 1 ) - TIME(11,0,0) ) -> 0.083333333 | L32: =IF(J32="","", IFERROR( HOUR(MIN(MOD(J32,1), TIME(11,0,0))) + MINUTE(MIN(MOD(J32,1), TIME(11,0,0)))/100, HOUR(MIN(MOD(TIMEVALUE(SUBSTITUTE(J32,CHAR(160),"")),1), TIME(11,0,0))) + MINUTE(MIN(MOD(TIMEVALUE(SUBSTITUTE(J32,CHAR(160),"")),1), TIME(11,0,0)))/100 ) ) -> 11 | M32: =IF(K32="","", IFERROR( HOUR(K32)+MINUTE(K32)/100, HOUR(TIMEVALUE(SUBSTITUTE(K32,CHAR(160),""))) +MINUTE(TIMEVALUE(SUBSTITUTE(K32,CHAR(160),"")))/100 ) ) -> 2
C33: =VLOOKUP(B33,Employees!A:B,2,FALSE) -> #N/A | H33: =F33 - E33 -> 0 | I33: =G33 - D33 -> 0 | J33: =I33 - H33 -> 0 | K33: =MAX( 0, MOD( IFERROR( J33, TIMEVALUE(SUBSTITUTE(J33,CHAR(160),"")) ), 1 ) - TIME(11,0,0) ) -> 0 | L33: =IF(J33="","", IFERROR( HOUR(MIN(MOD(J33,1), TIME(11,0,0))) + MINUTE(MIN(MOD(J33,1), TIME(11,0,0)))/100, HOUR(MIN(MOD(TIMEVALUE(SUBSTITUTE(J33,CHAR(160),"")),1), TIME(11,0,0))) + MINUTE(MIN(MOD(TIMEVALUE(SUBSTITUTE(J33,CHAR(160),"")),1), TIME(11,0,0)))/100 ) ) -> 0 | M33: =IF(K33="","", IFERROR( HOUR(K33)+MINUTE(K33)/100, HOUR(TIMEVALUE(SUBSTITUTE(K33,CHAR(160),""))) +MINUTE(TIMEVALUE(SUBSTITUTE(K33,CHAR(160),"")))/100 ) ) -> 0
A34: 46038 | B34: 2 | C34: =VLOOKUP(B34,Employees!A:B,2,FALSE) -> Umesh Kumar | D34: 0.33333333 | G34: 0.83333333 | H34: =F34 - E34 -> 0 | I34: =G34 - D34 -> 0.5 | J34: =I34 - H34 -> 0.5 | K34: =MAX( 0, MOD( IFERROR( J34, TIMEVALUE(SUBSTITUTE(J34,CHAR(160),"")) ), 1 ) - TIME(11,0,0) ) -> 0.041666667 | L34: =IF(J34="","", IFERROR( HOUR(MIN(MOD(J34,1), TIME(11,0,0))) + MINUTE(MIN(MOD(J34,1), TIME(11,0,0)))/100, HOUR(MIN(MOD(TIMEVALUE(SUBSTITUTE(J34,CHAR(160),"")),1), TIME(11,0,0))) + MINUTE(MIN(MOD(TIMEVALUE(SUBSTITUTE(J34,CHAR(160),"")),1), TIME(11,0,0)))/100 ) ) -> 11 | M34: =IF(K34="","", IFERROR( HOUR(K34)+MINUTE(K34)/100, HOUR(TIMEVALUE(SUBSTITUTE(K34,CHAR(160),""))) +MINUTE(TIMEVALUE(SUBSTITUTE(K34,CHAR(160),"")))/100 ) ) -> 1
B35: 2 | C35: =VLOOKUP(B35,Employees!A:B,2,FALSE) -> Umesh Kumar | D35: 0.83333333 | G35: 0.33333333 | H35: =F35 - E35 -> 0 | I35: =G35 - D35 -> -0.5 | J35: =I35 - H35 -> -0.5 | K35: =MAX( 0, MOD( IFERROR( J35, TIMEVALUE(SUBSTITUTE(J35,CHAR(160),"")) ), 1 ) - TIME(11,0,0) ) -> 0.041666667 | L35: =IF(J35="","", IFERROR( HOUR(MIN(MOD(J35,1), TIME(11,0,0))) + MINUTE(MIN(MOD(J35,1), TIME(11,0,0)))/100, HOUR(MIN(MOD(TIMEVALUE(SUBSTITUTE(J35,CHAR(160),"")),1), TIME(11,0,0))) + MINUTE(MIN(MOD(TIMEVALUE(SUBSTITUTE(J35,CHAR(160),"")),1), TIME(11,0,0)))/100 ) ) -> 11 | M35: =IF(K35="","", IFERROR( HOUR(K35)+MINUTE(K35)/100, HOUR(TIMEVALUE(SUBSTITUTE(K35,CHAR(160),""))) +MINUTE(TIMEVALUE(SUBSTITUTE(K35,CHAR(160),"")))/100 ) ) -> 1
A36: 46039 | B36: 1 | C36: =VLOOKUP(B36,Employees!A:B,2,FALSE) -> Rajat Hela | D36: 0.33333333 | E36: 0.54166667 | F36: 0.58333333 | G36: 0.83333333 | H36: =F36 - E36 -> 0.041666667 | I36: =G36 - D36 -> 0.5 | J36: =I36 - H36 -> 0.45833333 | K36: =MAX( 0, MOD( IFERROR( J36, TIMEVALUE(SUBSTITUTE(J36,CHAR(160),"")) ), 1 ) - TIME(11,0,0) ) -> 0 | L36: =IF(J36="","", IFERROR( HOUR(MIN(MOD(J36,1), TIME(11,0,0))) + MINUTE(MIN(MOD(J36,1), TIME(11,0,0)))/100, HOUR(MIN(MOD(TIMEVALUE(SUBSTITUTE(J36,CHAR(160),"")),1), TIME(11,0,0))) + MINUTE(MIN(MOD(TIMEVALUE(SUBSTITUTE(J36,CHAR(160),"")),1), TIME(11,0,0)))/100 ) ) -> 11 | M36: =IF(K36="","", IFERROR( HOUR(K36)+MINUTE(K36)/100, HOUR(TIMEVALUE(SUBSTITUTE(K36,CHAR(160),""))) +MINUTE(TIMEVALUE(SUBSTITUTE(K36,CHAR(160),"")))/100 ) ) -> 0
B37: 2 | C37: =VLOOKUP(B37,Employees!A:B,2,FALSE) -> Umesh Kumar | D37: 0.83333333 | G37: 0.33333333 | H37: =F37 - E37 -> 0 | I37: =G37 - D37 -> -0.5 | J37: =I37 - H37 -> -0.5 | K37: =MAX( 0, MOD( IFERROR( J37, TIMEVALUE(SUBSTITUTE(J37,CHAR(160),"")) ), 1 ) - TIME(11,0,0) ) -> 0.041666667 | L37: =IF(J37="","", IFERROR( HOUR(MIN(MOD(J37,1), TIME(11,0,0))) + MINUTE(MIN(MOD(J37,1), TIME(11,0,0)))/100, HOUR(MIN(MOD(TIMEVALUE(SUBSTITUTE(J37,CHAR(160),"")),1), TIME(11,0,0))) + MINUTE(MIN(MOD(TIMEVALUE(SUBSTITUTE(J37,CHAR(160),"")),1), TIME(11,0,0)))/100 ) ) -> 11 | M37: =IF(K37="","", IFERROR( HOUR(K37)+MINUTE(K37)/100, HOUR(TIMEVALUE(SUBSTITUTE(K37,CHAR(160),""))) +MINUTE(TIMEVALUE(SUBSTITUTE(K37,CHAR(160),"")))/100 ) ) -> 1
A38: 46040 | B38: 1 | C38: =VLOOKUP(B38,Employees!A:B,2,FALSE) -> Rajat Hela | D38: 0.33333333 | E38: 0.54166667 | F38: 0.58333333 | G38: 0.83333333 | H38: =F38 - E38 -> 0.041666667 | I38: =G38 - D38 -> 0.5 | J38: =I38 - H38 -> 0.45833333 | K38: =MAX( 0, MOD( IFERROR( J38, TIMEVALUE(SUBSTITUTE(J38,CHAR(160),"")) ), 1 ) - TIME(11,0,0) ) -> 0 | L38: =IF(J38="","", IFERROR( HOUR(MIN(MOD(J38,1), TIME(11,0,0))) + MINUTE(MIN(MOD(J38,1), TIME(11,0,0)))/100, HOUR(MIN(MOD(TIMEVALUE(SUBSTITUTE(J38,CHAR(160),"")),1), TIME(11,0,0))) + MINUTE(MIN(MOD(TIMEVALUE(SUBSTITUTE(J38,CHAR(160),"")),1), TIME(11,0,0)))/100 ) ) -> 11 | M38: =IF(K38="","", IFERROR( HOUR(K38)+MINUTE(K38)/100, HOUR(TIMEVALUE(SUBSTITUTE(K38,CHAR(160),""))) +MINUTE(TIMEVALUE(SUBSTITUTE(K38,CHAR(160),"")))/100 ) ) -> 0
B39: 2 | C39: =VLOOKUP(B39,Employees!A:B,2,FALSE) -> Umesh Kumar | D39: 0.83333333 | G39: 0.33333333 | H39: =F39 - E39 -> 0 | I39: =G39 - D39 -> -0.5 | J39: =I39 - H39 -> -0.5 | K39: =MAX( 0, MOD( IFERROR( J39, TIMEVALUE(SUBSTITUTE(J39,CHAR(160),"")) ), 1 ) - TIME(11,0,0) ) -> 0.041666667 | L39: =IF(J39="","", IFERROR( HOUR(MIN(MOD(J39,1), TIME(11,0,0))) + MINUTE(MIN(MOD(J39,1), TIME(11,0,0)))/100, HOUR(MIN(MOD(TIMEVALUE(SUBSTITUTE(J39,CHAR(160),"")),1), TIME(11,0,0))) + MINUTE(MIN(MOD(TIMEVALUE(SUBSTITUTE(J39,CHAR(160),"")),1), TIME(11,0,0)))/100 ) ) -> 11 | M39: =IF(K39="","", IFERROR( HOUR(K39)+MINUTE(K39)/100, HOUR(TIMEVALUE(SUBSTITUTE(K39,CHAR(160),""))) +MINUTE(TIMEVALUE(SUBSTITUTE(K39,CHAR(160),"")))/100 ) ) -> 1
A40: 46041 | B40: 1 | C40: =VLOOKUP(B40,Employees!A:B,2,FALSE) -> Rajat Hela | D40: 0.33333333 | E40: 0.54166667 | F40: 0.58333333 | G40: 0.83333333 | H40: =F40 - E40 -> 0.041666667 | I40: =G40 - D40 -> 0.5 | J40: =I40 - H40 -> 0.45833333 | K40: =MAX( 0, MOD( IFERROR( J40, TIMEVALUE(SUBSTITUTE(J40,CHAR(160),"")) ), 1 ) - TIME(11,0,0) ) -> 0 | L40: =IF(J40="","", IFERROR( HOUR(MIN(MOD(J40,1), TIME(11,0,0))) + MINUTE(MIN(MOD(J40,1), TIME(11,0,0)))/100, HOUR(MIN(MOD(TIMEVALUE(SUBSTITUTE(J40,CHAR(160),"")),1), TIME(11,0,0))) + MINUTE(MIN(MOD(TIMEVALUE(SUBSTITUTE(J40,CHAR(160),"")),1), TIME(11,0,0)))/100 ) ) -> 11 | M40: =IF(K40="","", IFERROR( HOUR(K40)+MINUTE(K40)/100, HOUR(TIMEVALUE(SUBSTITUTE(K40,CHAR(160),""))) +MINUTE(TIMEVALUE(SUBSTITUTE(K40,CHAR(160),"")))/100 ) ) -> 0
B41: 2 | C41: =VLOOKUP(B41,Employees!A:B,2,FALSE) -> Umesh Kumar | D41: 0.83333333 | G41: 0.33333333 | H41: =F41 - E41 -> 0 | I41: =G41 - D41 -> -0.5 | J41: =I41 - H41 -> -0.5 | K41: =MAX( 0, MOD( IFERROR( J41, TIMEVALUE(SUBSTITUTE(J41,CHAR(160),"")) ), 1 ) - TIME(11,0,0) ) -> 0.041666667 | L41: =IF(J41="","", IFERROR( HOUR(MIN(MOD(J41,1), TIME(11,0,0))) + MINUTE(MIN(MOD(J41,1), TIME(11,0,0)))/100, HOUR(MIN(MOD(TIMEVALUE(SUBSTITUTE(J41,CHAR(160),"")),1), TIME(11,0,0))) + MINUTE(MIN(MOD(TIMEVALUE(SUBSTITUTE(J41,CHAR(160),"")),1), TIME(11,0,0)))/100 ) ) -> 11 | M41: =IF(K41="","", IFERROR( HOUR(K41)+MINUTE(K41)/100, HOUR(TIMEVALUE(SUBSTITUTE(K41,CHAR(160),""))) +MINUTE(TIMEVALUE(SUBSTITUTE(K41,CHAR(160),"")))/100 ) ) -> 1
A42: 46042 | B42: 1 | C42: =VLOOKUP(B42,Employees!A:B,2,FALSE) -> Rajat Hela | D42: 0.33333333 | E42: 0.54166667 | F42: 0.58333333 | G42: 0.83333333 | H42: =F42 - E42 -> 0.041666667 | I42: =G42 - D42 -> 0.5 | J42: =I42 - H42 -> 0.45833333 | K42: =MAX( 0, MOD( IFERROR( J42, TIMEVALUE(SUBSTITUTE(J42,CHAR(160),"")) ), 1 ) - TIME(11,0,0) ) -> 0 | L42: =IF(J42="","", IFERROR( HOUR(MIN(MOD(J42,1), TIME(11,0,0))) + MINUTE(MIN(MOD(J42,1), TIME(11,0,0)))/100, HOUR(MIN(MOD(TIMEVALUE(SUBSTITUTE(J42,CHAR(160),"")),1), TIME(11,0,0))) + MINUTE(MIN(MOD(TIMEVALUE(SUBSTITUTE(J42,CHAR(160),"")),1), TIME(11,0,0)))/100 ) ) -> 11 | M42: =IF(K42="","", IFERROR( HOUR(K42)+MINUTE(K42)/100, HOUR(TIMEVALUE(SUBSTITUTE(K42,CHAR(160),""))) +MINUTE(TIMEVALUE(SUBSTITUTE(K42,CHAR(160),"")))/100 ) ) -> 0
B43: 2 | C43: =VLOOKUP(B43,Employees!A:B,2,FALSE) -> Umesh Kumar | D43: 0.83333333 | G43: 0.33333333 | H43: =F43 - E43 -> 0 | I43: =G43 - D43 -> -0.5 | J43: =I43 - H43 -> -0.5 | K43: =MAX( 0, MOD( IFERROR( J43, TIMEVALUE(SUBSTITUTE(J43,CHAR(160),"")) ), 1 ) - TIME(11,0,0) ) -> 0.041666667 | L43: =IF(J43="","", IFERROR( HOUR(MIN(MOD(J43,1), TIME(11,0,0))) + MINUTE(MIN(MOD(J43,1), TIME(11,0,0)))/100, HOUR(MIN(MOD(TIMEVALUE(SUBSTITUTE(J43,CHAR(160),"")),1), TIME(11,0,0))) + MINUTE(MIN(MOD(TIMEVALUE(SUBSTITUTE(J43,CHAR(160),"")),1), TIME(11,0,0)))/100 ) ) -> 11 | M43: =IF(K43="","", IFERROR( HOUR(K43)+MINUTE(K43)/100, HOUR(TIMEVALUE(SUBSTITUTE(K43,CHAR(160),""))) +MINUTE(TIMEVALUE(SUBSTITUTE(K43,CHAR(160),"")))/100 ) ) -> 1
A44: 46043 | G44: Wednesday | L44: =IF(J44="","", IFERROR( HOUR(MIN(MOD(J44,1), TIME(11,0,0))) + MINUTE(MIN(MOD(J44,1), TIME(11,0,0)))/100, HOUR(MIN(MOD(TIMEVALUE(SUBSTITUTE(J44,CHAR(160),"")),1), TIME(11,0,0))) + MINUTE(MIN(MOD(TIMEVALUE(SUBSTITUTE(J44,CHAR(160),"")),1), TIME(11,0,0)))/100 ) ) | M44: =IF(K44="","", IFERROR( HOUR(K44)+MINUTE(K44)/100, HOUR(TIMEVALUE(SUBSTITUTE(K44,CHAR(160),""))) +MINUTE(TIMEVALUE(SUBSTITUTE(K44,CHAR(160),"")))/100 ) )
...

Sheet 02-2026
A1: 46054
A5: Emp ID | B5: Employee Name | C5: Contact | D5: Department | E5: Designation | F5: Basic Salary | G5: Per Day Salary | H5: Per Hour Salary | I5: Total Hours | J5: Total OT (hrs) | K5: Salary Earned
A6: 1 | B6: =VLOOKUP(A6,Employees!A:B,2,FALSE) -> Rajat Hela | C6: =VLOOKUP(A6,Employees!A:C,3,FALSE) -> 9023270731 | D6: =VLOOKUP(A6,Employees!A:D,4,FALSE) -> Production | E6: =VLOOKUP(A6,Employees!A:E,5,FALSE) -> CNC Machine Operator | F6: =VLOOKUP(A6,Employees!A:F,6,FALSE) -> 17000 | G6: =VLOOKUP(A6,Employees!A:G,7,FALSE) -> 653.84615 | H6: =VLOOKUP(A6,Employees!A:H,8,FALSE) -> 59.440559 | I6: =SUMIFS('02-2026'!$L$10:$L$306, '02-2026'!$B$10:$B$306, $A6) -> 263.3 | J6: =SUMIFS('02-2026'!$M$10:$M$306, '02-2026'!$B$10:$B$306, $A6) -> 13 | K6: =('02-2026'!$I6+'02-2026'!$J6)*'02-2026'!$H6 -> 16423.427
A7: 2 | B7: =VLOOKUP(A7,Employees!A:B,2,FALSE) -> Umesh Kumar | C7: =VLOOKUP(A7,Employees!A:C,3,FALSE) | D7: =VLOOKUP(A7,Employees!A:D,4,FALSE) -> Production | E7: =VLOOKUP(A7,Employees!A:E,5,FALSE) -> CNC Machine Operator | F7: 18000 | G7: =VLOOKUP(A7,Employees!A:G,7,FALSE) -> 692.30769 | H7: =VLOOKUP(A7,Employees!A:H,8,FALSE) -> 62.937063 | I7: =SUMIFS('02-2026'!$L$10:$L$306, '02-2026'!$B$10:$B$306, $A7) -> 275.3 | J7: =SUMIFS('02-2026'!$M$10:$M$306, '02-2026'!$B$10:$B$306, $A7) -> 12 | K7: =('02-2026'!$I7+'02-2026'!$J7)*'02-2026'!$H7 -> 18081.818
A9: Date | B9: Employee ID | C9: Employee Name | D9: Check-In | E9: Break Start | F9: Break End | G9: Check-Out | H9: Total Break (hrs) | I9: Total Working (hrs) | J9: Net Working (hrs) | K9: Over Time (hrs) | L9: NW (For Calc) | M9: Ot (For Calc)
L10: =IF(J10="","", IFERROR( HOUR(J10)+MINUTE(J10)/100, HOUR(TIMEVALUE(SUBSTITUTE(J10,CHAR(160),""))) +MINUTE(TIMEVALUE(SUBSTITUTE(J10,CHAR(160),"")))/100 ) ) | M10: =IF(K10="","", IFERROR( HOUR(K10)+MINUTE(K10)/100, HOUR(TIMEVALUE(SUBSTITUTE(K10,CHAR(160),""))) +MINUTE(TIMEVALUE(SUBSTITUTE(K10,CHAR(160),"")))/100 ) )
A11: 46054 | B11: 1 | C11: =VLOOKUP(B11,Employees!A:B,2,FALSE) -> Rajat Hela | D11: 0.33333333 | E11: 0.54166667 | F11: 0.58333333 | G11: 0.83333333 | H11: =F11 - E11 -> 0.041666667 | I11: =G11 - D11 -> 0.5 | J11: =I11 - H11 -> 0.45833333 | K11: =MAX( 0, MOD( IFERROR( J11, TIMEVALUE(SUBSTITUTE(J11,CHAR(160),"")) ), 1 ) - TIME(11,0,0) ) -> 0 | L11: =IF(J11="","", IFERROR( HOUR(MIN(MOD(J11,1), TIME(11,0,0))) + MINUTE(MIN(MOD(J11,1), TIME(11,0,0)))/100, HOUR(MIN(MOD(TIMEVALUE(SUBSTITUTE(J11,CHAR(160),"")),1), TIME(11,0,0))) + MINUTE(MIN(MOD(TIMEVALUE(SUBSTITUTE(J11,CHAR(160),"")),1), TIME(11,0,0)))/100 ) ) -> 11 | M11: =IF(K11="","", IFERROR( HOUR(K11)+MINUTE(K11)/100, HOUR(TIMEVALUE(SUBSTITUTE(K11,CHAR(160),""))) +MINUTE(TIMEVALUE(SUBSTITUTE(K11,CHAR(160),"")))/100 ) ) -> 0
B12: 2 | C12: =VLOOKUP(B12,Employees!A:B,2,FALSE) -> Umesh Kumar | D12: 0.83333333 | G12: 0.33333333 | H12: =F12 - E12 -> 0 | I12: =G12 - D12 -> -0.5 | J12: =I12 - H12 -> -0.5 | K12: =MAX( 0, MOD( IFERROR( J12, TIMEVALUE(SUBSTITUTE(J12,CHAR(160),"")) ), 1 ) - TIME(11,0,0) ) -> 0.041666667 | L12: =IF(J12="","", IFERROR( HOUR(MIN(MOD(J12,1), TIME(11,0,0))) + MINUTE(MIN(MOD(J12,1), TIME(11,0,0)))/100, HOUR(MIN(MOD(TIMEVALUE(SUBSTITUTE(J12,CHAR(160),"")),1), TIME(11,0,0))) + MINUTE(MIN(MOD(TIMEVALUE(SUBSTITUTE(J12,CHAR(160),"")),1), TIME(11,0,0)))/100 ) ) -> 11 | M12: =IF(K12="","", IFERROR( HOUR(K12)+MINUTE(K12)/100, HOUR(TIMEVALUE(SUBSTITUTE(K12,CHAR(160),""))) +MINUTE(TIMEVALUE(SUBSTITUTE(K12,CHAR(160),"")))/100 ) ) -> 1
A13: 46055 | B13: 1 | C13: =VLOOKUP(B13,Employees!A:B,2,FALSE) -> Rajat Hela | D13: 0.33333333 | E13: 0.54166667 | F13: 0.58333333 | G13: 0.8125 | H13: =F13 - E13 -> 0.041666667 | I13: =G13 - D13 -> 0.47916667 | J13: =I13 - H13 -> 0.4375 | K13: =MAX( 0, MOD( IFERROR( J13, TIMEVALUE(SUBSTITUTE(J13,CHAR(160),"")) ), 1 ) - TIME(11,0,0) ) -> 0 | L13: =IF(J13="","", IFERROR( HOUR(MIN(MOD(J13,1), TIME(11,0,0))) + MINUTE(MIN(MOD(J13,1), TIME(11,0,0)))/100, HOUR(MIN(MOD(TIMEVALUE(SUBSTITUTE(J13,CHAR(160),"")),1), TIME(11,0,0))) + MINUTE(MIN(MOD(TIMEVALUE(SUBSTITUTE(J13,CHAR(160),"")),1), TIME(11,0,0)))/100 ) ) -> 10.3 | M13: =IF(K13="","", IFERROR( HOUR(K13)+MINUTE(K13)/100, HOUR(TIMEVALUE(SUBSTITUTE(K13,CHAR(160),""))) +MINUTE(TIMEVALUE(SUBSTITUTE(K13,CHAR(160),"")))/100 ) ) -> 0
B14: 2 | C14: =VLOOKUP(B14,Employees!A:B,2,FALSE) -> Umesh Kumar | D14: 0.83333333 | G14: 0.33333333 | H14: =F14 - E14 -> 0 | I14: =G14 - D14 -> -0.5 | J14: =I14 - H14 -> -0.5 | K14: =MAX( 0, MOD( IFERROR( J14, TIMEVALUE(SUBSTITUTE(J14,CHAR(160),"")) ), 1 ) - TIME(11,0,0) ) -> 0.041666667 | L14: =IF(J14="","", IFERROR( HOUR(MIN(MOD(J14,1), TIME(11,0,0))) + MINUTE(MIN(MOD(J14,1), TIME(11,0,0)))/100, HOUR(MIN(MOD(TIMEVALUE(SUBSTITUTE(J14,CHAR(160),"")),1), TIME(11,0,0))) + MINUTE(MIN(MOD(TIMEVALUE(SUBSTITUTE(J14,CHAR(160),"")),1), TIME(11,0,0)))/100 ) ) -> 11 | M14: =IF(K14="","", IFERROR( HOUR(K14)+MINUTE(K14)/100, HOUR(TIMEVALUE(SUBSTITUTE(K14,CHAR(160),""))) +MINUTE(TIMEVALUE(SUBSTITUTE(K14,CHAR(160),"")))/100 ) ) -> 1
A15: 46056 | B15: 1 | C15: =VLOOKUP(B15,Employees!A:B,2,FALSE) -> Rajat Hela | D15: 0.33333333 | E15: 0.54166667 | F15: 0.58333333 | G15: 0.83333333 | H15: =F15 - E15 -> 0.041666667 | I15: =G15 - D15 -> 0.5 | J15: =I15 - H15 -> 0.45833333 | K15: =MAX( 0, MOD( IFERROR( J15, TIMEVALUE(SUBSTITUTE(J15,CHAR(160),"")) ), 1 ) - TIME(11,0,0) ) -> 0 | L15: =IF(J15="","", IFERROR( HOUR(MIN(MOD(J15,1), TIME(11,0,0))) + MINUTE(MIN(MOD(J15,1), TIME(11,0,0)))/100, HOUR(MIN(MOD(TIMEVALUE(SUBSTITUTE(J15,CHAR(160),"")),1), TIME(11,0,0))) + MINUTE(MIN(MOD(TIMEVALUE(SUBSTITUTE(J15,CHAR(160),"")),1), TIME(11,0,0)))/100 ) ) -> 11 | M15: =IF(K15="","", IFERROR( HOUR(K15)+MINUTE(K15)/100, HOUR(TIMEVALUE(SUBSTITUTE(K15,CHAR(160),""))) +MINUTE(TIMEVALUE(SUBSTITUTE(K15,CHAR(160),"")))/100 ) ) -> 0
B16: 2 | C16: =VLOOKUP(B16,Employees!A:B,2,FALSE) -> Umesh Kumar | D16: 0.83333333 | G16: 0.33333333 | H16: =F16 - E16 -> 0 | I16: =G16 - D16 -> -0.5 | J16: =I16 - H16 -> -0.5 | K16: =MAX( 0, MOD( IFERROR( J16, TIMEVALUE(SUBSTITUTE(J16,CHAR(160),"")) ), 1 ) - TIME(11,0,0) ) -> 0.041666667 | L16: =IF(J16="","", IFERROR( HOUR(MIN(MOD(J16,1), TIME(11,0,0))) + MINUTE(MIN(MOD(J16,1), TIME(11,0,0)))/100, HOUR(MIN(MOD(TIMEVALUE(SUBSTITUTE(J16,CHAR(160),"")),1), TIME(11,0,0))) + MINUTE(MIN(MOD(TIMEVALUE(SUBSTITUTE(J16,CHAR(160),"")),1), TIME(11,0,0)))/100 ) ) -> 11 | M16: =IF(K16="","", IFERROR( HOUR(K16)+MINUTE(K16)/100, HOUR(TIMEVALUE(SUBSTITUTE(K16,CHAR(160),""))) +MINUTE(TIMEVALUE(SUBSTITUTE(K16,CHAR(160),"")))/100 ) ) -> 1
A17: 46057 | G17: Wednesday | L17: =IF(J17="","", IFERROR( HOUR(MIN(MOD(J17,1), TIME(11,0,0))) + MINUTE(MIN(MOD(J17,1), TIME(11,0,0)))/100, HOUR(MIN(MOD(TIMEVALUE(SUBSTITUTE(J17,CHAR(160),"")),1), TIME(11,0,0))) + MINUTE(MIN(MOD(TIMEVALUE(SUBSTITUTE(J17,CHAR(160),"")),1), TIME(11,0,0)))/100 ) ) | M17: =IF(K17="","", IFERROR( HOUR(K17)+MINUTE(K17)/100, HOUR(TIMEVALUE(SUBSTITUTE(K17,CHAR(160),""))) +MINUTE(TIMEVALUE(SUBSTITUTE(K17,CHAR(160),"")))/100 ) )
A18: 46058 | B18: 2 | C18: =VLOOKUP(B18,Employees!A:B,2,FALSE) -> Umesh Kumar | D18: 0.33333333 | E18: 0.54166667 | F18: 0.58333333 | G18: 0.83333333 | H18: =F18 - E18 -> 0.041666667 | I18: =G18 - D18 -> 0.5 | J18: =I18 - H18 -> 0.45833333 | K18: =MAX( 0, MOD( IFERROR( J18, TIMEVALUE(SUBSTITUTE(J18,CHAR(160),"")) ), 1 ) - TIME(11,0,0) ) -> 0 | L18: =IF(J18="","", IFERROR( HOUR(MIN(MOD(J18,1), TIME(11,0,0))) + MINUTE(MIN(MOD(J18,1), TIME(11,0,0)))/100, HOUR(MIN(MOD(TIMEVALUE(SUBSTITUTE(J18,CHAR(160),"")),1), TIME(11,0,0))) + MINUTE(MIN(MOD(TIMEVALUE(SUBSTITUTE(J18,CHAR(160),"")),1), TIME(11,0,0)))/100 ) ) -> 11 | M18: =IF(K18="","", IFERROR( HOUR(K18)+MINUTE(K18)/100, HOUR(TIMEVALUE(SUBSTITUTE(K18,CHAR(160),""))) +MINUTE(TIMEVALUE(SUBSTITUTE(K18,CHAR(160),"")))/100 ) ) -> 0
B19: 1 | C19: =VLOOKUP(B19,Employees!A:B,2,FALSE) -> Rajat Hela | D19: 0.83333333 | G19: 0.33333333 | H19: =F19 - E19 -> 0 | I19: =G19 - D19 -> -0.5 | J19: =I19 - H19 -> -0.5 | K19: =MAX( 0, MOD( IFERROR( J19, TIMEVALUE(SUBSTITUTE(J19,CHAR(160),"")) ), 1 ) - TIME(11,0,0) ) -> 0.041666667 | L19: =IF(J19="","", IFERROR( HOUR(MIN(MOD(J19,1), TIME(11,0,0))) + MINUTE(MIN(MOD(J19,1), TIME(11,0,0)))/100, HOUR(MIN(MOD(TIMEVALUE(SUBSTITUTE(J19,CHAR(160),"")),1), TIME(11,0,0))) + MINUTE(MIN(MOD(TIMEVALUE(SUBSTITUTE(J19,CHAR(160),"")),1), TIME(11,0,0)))/100 ) ) -> 11 | M19: =IF(K19="","", IFERROR( HOUR(K19)+MINUTE(K19)/100, HOUR(TIMEVALUE(SUBSTITUTE(K19,CHAR(160),""))) +MINUTE(TIMEVALUE(SUBSTITUTE(K19,CHAR(160),"")))/100 ) ) -> 1
A20: 46059 | B20: 2 | C20: =VLOOKUP(B20,Employees!A:B,2,FALSE) -> Umesh Kumar | D20: 0.33333333 | E20: 0.54166667 | F20: 0.58333333 | G20: 0.875 | H20: =F20 - E20 -> 0.041666667 | I20: =G20 - D20 -> 0.54166667 | J20: =I20 - H20 -> 0.5 | K20: =MAX( 0, MOD( IFERROR( J20, TIMEVALUE(SUBSTITUTE(J20,CHAR(160),"")) ), 1 ) - TIME(11,0,0) ) -> 0.041666667 | L20: =IF(J20="","", IFERROR( HOUR(MIN(MOD(J20,1), TIME(11,0,0))) + MINUTE(MIN(MOD(J20,1), TIME(11,0,0)))/100, HOUR(MIN(MOD(TIMEVALUE(SUBSTITUTE(J20,CHAR(160),"")),1), TIME(11,0,0))) + MINUTE(MIN(MOD(TIMEVALUE(SUBSTITUTE(J20,CHAR(160),"")),1), TIME(11,0,0)))/100 ) ) -> 11 | M20: =IF(K20="","", IFERROR( HOUR(K20)+MINUTE(K20)/100, HOUR(TIMEVALUE(SUBSTITUTE(K20,CHAR(160),""))) +MINUTE(TIMEVALUE(SUBSTITUTE(K20,CHAR(160),"")))/100 ) ) -> 1
B21: 1 | C21: =VLOOKUP(B21,Employees!A:B,2,FALSE) -> Rajat Hela | D21: 0.83333333 | G21: 0.33333333 | H21: =F21 - E21 -> 0 | I21: =G21 - D21 -> -0.5 | J21: =I21 - H21 -> -0.5 | K21: =MAX( 0, MOD( IFERROR( J21, TIMEVALUE(SUBSTITUTE(J21,CHAR(160),"")) ), 1 ) - TIME(11,0,0) ) -> 0.041666667 | L21: =IF(J21="","", IFERROR( HOUR(MIN(MOD(J21,1), TIME(11,0,0))) + MINUTE(MIN(MOD(J21,1), TIME(11,0,0)))/100, HOUR(MIN(MOD(TIMEVALUE(SUBSTITUTE(J21,CHAR(160),"")),1), TIME(11,0,0))) + MINUTE(MIN(MOD(TIMEVALUE(SUBSTITUTE(J21,CHAR(160),"")),1), TIME(11,0,0)))/100 ) ) -> 11 | M21: =IF(K21="","", IFERROR( HOUR(K21)+MINUTE(K21)/100, HOUR(TIMEVALUE(SUBSTITUTE(K21,CHAR(160),""))) +MINUTE(TIMEVALUE(SUBSTITUTE(K21,CHAR(160),"")))/100 ) ) -> 1
A22: 46060 | B22: 2 | C22: =VLOOKUP(B22,Employees!A:B,2,FALSE) -> Umesh Kumar | D22: 0.33333333 | E22: 0.54166667 | F22: 0.58333333 | G22: 0.83333333 | H22: =F22 - E22 -> 0.041666667 | I22: =G22 - D22 -> 0.5 | J22: =I22 - H22 -> 0.45833333 | K22: =MAX( 0, MOD( IFERROR( J22, TIMEVALUE(SUBSTITUTE(J22,CHAR(160),"")) ), 1 ) - TIME(11,0,0) ) -> 0 | L22: =IF(J22="","", IFERROR( HOUR(MIN(MOD(J22,1), TIME(11,0,0))) + MINUTE(MIN(MOD(J22,1), TIME(11,0,0)))/100, HOUR(MIN(MOD(TIMEVALUE(SUBSTITUTE(J22,CHAR(160),"")),1), TIME(11,0,0))) + MINUTE(MIN(MOD(TIMEVALUE(SUBSTITUTE(J22,CHAR(160),"")),1), TIME(11,0,0)))/100 ) ) -> 11 | M22: =IF(K22="","", IFERROR( HOUR(K22)+MINUTE(K22)/100, HOUR(TIMEVALUE(SUBSTITUTE(K22,CHAR(160),""))) +MINUTE(TIMEVALUE(SUBSTITUTE(K22,CHAR(160),"")))/100 ) ) -> 0
B23: 1 | C23: =VLOOKUP(B23,Employees!A:B,2,FALSE) -> Rajat Hela | D23: 0.83333333 | G23: 0.33333333 | H23: =F23 - E23 -> 0 | I23: =G23 - D23 -> -0.5 | J23: =I23 - H23 -> -0.5 | K23: =MAX( 0, MOD( IFERROR( J23, TIMEVALUE(SUBSTITUTE(J23,CHAR(160),"")) ), 1 ) - TIME(11,0,0) ) -> 0.041666667 | L23: =IF(J23="","", IFERROR( HOUR(MIN(MOD(J23,1), TIME(11,0,0))) + MINUTE(MIN(MOD(J23,1), TIME(11,0,0)))/100, HOUR(MIN(MOD(TIMEVALUE(SUBSTITUTE(J23,CHAR(160),"")),1), TIME(11,0,0))) + MINUTE(MIN(MOD(TIMEVALUE(SUBSTITUTE(J23,CHAR(160),"")),1), TIME(11,0,0)))/100 ) ) -> 11 | M23: =IF(K23="","", IFERROR( HOUR(K23)+MINUTE(K23)/100, HOUR(TIMEVALUE(SUBSTITUTE(K23,CHAR(160),""))) +MINUTE(TIMEVALUE(SUBSTITUTE(K23,CHAR(160),"")))/100 ) ) -> 1
A24: 46061 | B24: 2 | C24: =VLOOKUP(B24,Employees!A:B,2,FALSE) -> Umesh Kumar | D24: 0.33333333 | E24: 0.54166667 | F24: 0.58333333 | G24: 0.83333333 | H24: =F24 - E24 -> 0.041666667 | I24: =G24 - D24 -> 0.5 | J24: =I24 - H24 -> 0.45833333 | K24: =MAX( 0, MOD( IFERROR( J24, TIMEVALUE(SUBSTITUTE(J24,CHAR(160),"")) ), 1 ) - TIME(11,0,0) ) -> 0 | L24: =IF(J24="","", IFERROR( HOUR(MIN(MOD(J24,1), TIME(11,0,0))) + MINUTE(MIN(MOD(J24,1), TIME(11,0,0)))/100, HOUR(MIN(MOD(TIMEVALUE(SUBSTITUTE(J24,CHAR(160),"")),1), TIME(11,0,0))) + MINUTE(MIN(MOD(TIMEVALUE(SUBSTITUTE(J24,CHAR(160),"")),1), TIME(11,0,0)))/100 ) ) -> 11 | M24: =IF(K24="","", IFERROR( HOUR(K24)+MINUTE(K24)/100, HOUR(TIMEVALUE(SUBSTITUTE(K24,CHAR(160),""))) +MINUTE(TIMEVALUE(SUBSTITUTE(K24,CHAR(160),"")))/100 ) ) -> 0
B25: 1 | C25: =VLOOKUP(B25,Employees!A:B,2,FALSE) -> Rajat Hela | D25: 0.83333333 | G25: 0.33333333 | H25: =F25 - E25 -> 0 | I25: =G25 - D25 -> -0.5 | J25: =I25 - H25 -> -0.5 | K25: =MAX( 0, MOD( IFERROR( J25, TIMEVALUE(SUBSTITUTE(J25,CHAR(160),"")) ), 1 ) - TIME(11,0,0) ) -> 0.041666667 | L25: =IF(J25="","", IFERROR( HOUR(MIN(MOD(J25,1), TIME(11,0,0))) + MINUTE(MIN(MOD(J25,1), TIME(11,0,0)))/100, HOUR(MIN(MOD(TIMEVALUE(SUBSTITUTE(J25,CHAR(160),"")),1), TIME(11,0,0))) + MINUTE(MIN(MOD(TIMEVALUE(SUBSTITUTE(J25,CHAR(160),"")),1), TIME(11,0,0)))/100 ) ) -> 11 | M25: =IF(K25="","", IFERROR( HOUR(K25)+MINUTE(K25)/100, HOUR(TIMEVALUE(SUBSTITUTE(K25,CHAR(160),""))) +MINUTE(TIMEVALUE(SUBSTITUTE(K25,CHAR(160),"")))/100 ) ) -> 1
A26: 46062 | B26: 2 | C26: =VLOOKUP(B26,Employees!A:B,2,FALSE) -> Umesh Kumar | D26: 0.33333333 | E26: 0.54166667 | F26: 0.58333333 | G26: 0.83333333 | H26: =F26 - E26 -> 0.041666667 | I26: =G26 - D26 -> 0.5 | J26: =I26 - H26 -> 0.45833333 | K26: =MAX( 0, MOD( IFERROR( J26, TIMEVALUE(SUBSTITUTE(J26,CHAR(160),"")) ), 1 ) - TIME(11,0,0) ) -> 0 | L26: =IF(J26="","", IFERROR( HOUR(MIN(MOD(J26,1), TIME(11,0,0))) + MINUTE(MIN(MOD(J26,1), TIME(11,0,0)))/100, HOUR(MIN(MOD(TIMEVALUE(SUBSTITUTE(J26,CHAR(160),"")),1), TIME(11,0,0))) + MINUTE(MIN(MOD(TIMEVALUE(SUBSTITUTE(J26,CHAR(160),"")),1), TIME(11,0,0)))/100 ) ) -> 11 | M26: =IF(K26="","", IFERROR( HOUR(K26)+MINUTE(K26)/100, HOUR(TIMEVALUE(SUBSTITUTE(K26,CHAR(160),""))) +MINUTE(TIMEVALUE(SUBSTITUTE(K26,CHAR(160),"")))/100 ) ) -> 0
B27: 1 | C27: =VLOOKUP(B27,Employees!A:B,2,FALSE) -> Rajat Hela | D27: 0.83333333 | G27: 0.33333333 | H27: =F27 - E27 -> 0 | I27: =G27 - D27 -> -0.5 | J27: =I27 - H27 -> -0.5 | K27: =MAX( 0, MOD( IFERROR( J27, TIMEVALUE(SUBSTITUTE(J27,CHAR(160),"")) ), 1 ) - TIME(11,0,0) ) -> 0.041666667 | L27: =IF(J27="","", IFERROR( HOUR(MIN(MOD(J27,1), TIME(11,0,0))) + MINUTE(MIN(MOD(J27,1), TIME(11,0,0)))/100, HOUR(MIN(MOD(TIMEVALUE(SUBSTITUTE(J27,CHAR(160),"")),1), TIME(11,0,0))) + MINUTE(MIN(MOD(TIMEVALUE(SUBSTITUTE(J27,CHAR(160),"")),1), TIME(11,0,0)))/100 ) ) -> 11 | M27: =IF(K27="","", IFERROR( HOUR(K27)+MINUTE(K27)/100, HOUR(TIMEVALUE(SUBSTITUTE(K27,CHAR(160),""))) +MINUTE(TIMEVALUE(SUBSTITUTE(K27,CHAR(160),"")))/100 ) ) -> 1
A28: 46063 | B28: 2 | C28: =VLOOKUP(B28,Employees!A:B,2,FALSE) -> Umesh Kumar | D28: 0.33333333 | E28: 0.54166667 | F28: 0.58333333 | G28: 0.83333333 | H28: =F28 - E28 -> 0.041666667 | I28: =G28 - D28 -> 0.5 | J28: =I28 - H28 -> 0.45833333 | K28: =MAX( 0, MOD( IFERROR( J28, TIMEVALUE(SUBSTITUTE(J28,CHAR(160),"")) ), 1 ) - TIME(11,0,0) ) -> 0 | L28: =IF(J28="","", IFERROR( HOUR(MIN(MOD(J28,1), TIME(11,0,0))) + MINUTE(MIN(MOD(J28,1), TIME(11,0,0)))/100, HOUR(MIN(MOD(TIMEVALUE(SUBSTITUTE(J28,CHAR(160),"")),1), TIME(11,0,0))) + MINUTE(MIN(MOD(TIMEVALUE(SUBSTITUTE(J28,CHAR(160),"")),1), TIME(11,0,0)))/100 ) ) -> 11 | M28: =IF(K28="","", IFERROR( HOUR(K28)+MINUTE(K28)/100, HOUR(TIMEVALUE(SUBSTITUTE(K28,CHAR(160),""))) +MINUTE(TIMEVALUE(SUBSTITUTE(K28,CHAR(160),"")))/100 ) ) -> 0
B29: 1 | C29: =VLOOKUP(B29,Employees!A:B,2,FALSE) -> Rajat Hela | D29: 0.83333333 | G29: 0.33333333 | H29: =F29 - E29 -> 0 | I29: =G29 - D29 -> -0.5 | J29: =I29 - H29 -> -0.5 | K29: =MAX( 0, MOD( IFERROR( J29, TIMEVALUE(SUBSTITUTE(J29,CHAR(160),"")) ), 1 ) - TIME(11,0,0) ) -> 0.041666667 | L29: =IF(J29="","", IFERROR( HOUR(MIN(MOD(J29,1), TIME(11,0,0))) + MINUTE(MIN(MOD(J29,1), TIME(11,0,0)))/100, HOUR(MIN(MOD(TIMEVALUE(SUBSTITUTE(J29,CHAR(160),"")),1), TIME(11,0,0))) + MINUTE(MIN(MOD(TIMEVALUE(SUBSTITUTE(J29,CHAR(160),"")),1), TIME(11,0,0)))/100 ) ) -> 11 | M29: =IF(K29="","", IFERROR( HOUR(K29)+MINUTE(K29)/100, HOUR(TIMEVALUE(SUBSTITUTE(K29,CHAR(160),""))) +MINUTE(TIMEVALUE(SUBSTITUTE(K29,CHAR(160),"")))/100 ) ) -> 1
A30: 46064 | B30: 2 | C30: =VLOOKUP(B30,Employees!A:B,2,FALSE) -> Umesh Kumar | D30: 0.33333333 | E30: 0.54166667 | F30: 0.58333333 | G30: 0.75 | H30: 0 | I30: 0.41666667 | J30: 0.375 | K30: 0 | L30: =IF(J30="","", IFERROR( HOUR(MIN(MOD(J30,1), TIME(11,0,0))) + MINUTE(MIN(MOD(J30,1), TIME(11,0,0)))/100, HOUR(MIN(MOD(TIMEVALUE(SUBSTITUTE(J30,CHAR(160),"")),1), TIME(11,0,0))) + MINUTE(MIN(MOD(TIMEVALUE(SUBSTITUTE(J30,CHAR(160),"")),1), TIME(11,0,0)))/100 ) ) -> 9 | M30: =IF(K30="","", IFERROR( HOUR(K30)+MINUTE(K30)/100, HOUR(TIMEVALUE(SUBSTITUTE(K30,CHAR(160),""))) +MINUTE(TIMEVALUE(SUBSTITUTE(K30,CHAR(160),"")))/100 ) ) -> 0
A31: 46065 | B31: 1 | C31: =VLOOKUP(B31,Employees!A:B,2,FALSE) -> Rajat Hela | D31: 0.33333333 | E31: 0.54166667 | F31: 0.58333333 | G31: 0.83333333 | H31: =F31 - E31 -> 0.041666667 | I31: =G31 - D31 -> 0.5 | J31: =I31 - H31 -> 0.45833333 | K31: =MAX( 0, MOD( IFERROR( J31, TIMEVALUE(SUBSTITUTE(J31,CHAR(160),"")) ), 1 ) - TIME(11,0,0) ) -> 0 | L31: =IF(J31="","", IFERROR( HOUR(MIN(MOD(J31,1), TIME(11,0,0))) + MINUTE(MIN(MOD(J31,1), TIME(11,0,0)))/100, HOUR(MIN(MOD(TIMEVALUE(SUBSTITUTE(J31,CHAR(160),"")),1), TIME(11,0,0))) + MINUTE(MIN(MOD(TIMEVALUE(SUBSTITUTE(J31,CHAR(160),"")),1), TIME(11,0,0)))/100 ) ) -> 11 | M31: =IF(K31="","", IFERROR( HOUR(K31)+MINUTE(K31)/100, HOUR(TIMEVALUE(SUBSTITUTE(K31,CHAR(160),""))) +MINUTE(TIMEVALUE(SUBSTITUTE(K31,CHAR(160),"")))/100 ) ) -> 0
B32: 2 | C32: =VLOOKUP(B32,Employees!A:B,2,FALSE) -> Umesh Kumar | D32: 0.83333333 | G32: 0.33333333 | H32: =F32 - E32 -> 0 | I32: =G32 - D32 -> -0.5 | J32: =I32 - H32 -> -0.5 | K32: =MAX( 0, MOD( IFERROR( J32, TIMEVALUE(SUBSTITUTE(J32,CHAR(160),"")) ), 1 ) - TIME(11,0,0) ) -> 0.041666667 | L32: =IF(J32="","", IFERROR( HOUR(MIN(MOD(J32,1), TIME(11,0,0))) + MINUTE(MIN(MOD(J32,1), TIME(11,0,0)))/100, HOUR(MIN(MOD(TIMEVALUE(SUBSTITUTE(J32,CHAR(160),"")),1), TIME(11,0,0))) + MINUTE(MIN(MOD(TIMEVALUE(SUBSTITUTE(J32,CHAR(160),"")),1), TIME(11,0,0)))/100 ) ) -> 11 | M32: =IF(K32="","", IFERROR( HOUR(K32)+MINUTE(K32)/100, HOUR(TIMEVALUE(SUBSTITUTE(K32,CHAR(160),""))) +MINUTE(TIMEVALUE(SUBSTITUTE(K32,CHAR(160),"")))/100 ) ) -> 1
A33: 46066 | B33: 1 | C33: =VLOOKUP(B33,Employees!A:B,2,FALSE) -> Rajat Hela | D33: 0.33333333 | E33: 0.54166667 | F33: 0.58333333 | G33: 0.83333333 | H33: =F33 - E33 -> 0.041666667 | I33: =G33 - D33 -> 0.5 | J33: =I33 - H33 -> 0.45833333 | K33: =MAX( 0, MOD( IFERROR( J33, TIMEVALUE(SUBSTITUTE(J33,CHAR(160),"")) ), 1 ) - TIME(11,0,0) ) -> 0 | L33: =IF(J33="","", IFERROR( HOUR(MIN(MOD(J33,1), TIME(11,0,0))) + MINUTE(MIN(MOD(J33,1), TIME(11,0,0)))/100, HOUR(MIN(MOD(TIMEVALUE(SUBSTITUTE(J33,CHAR(160),"")),1), TIME(11,0,0))) + MINUTE(MIN(MOD(TIMEVALUE(SUBSTITUTE(J33,CHAR(160),"")),1), TIME(11,0,0)))/100 ) ) -> 11 | M33: =IF(K33="","", IFERROR( HOUR(K33)+MINUTE(K33)/100, HOUR(TIMEVALUE(SUBSTITUTE(K33,CHAR(160),""))) +MINUTE(TIMEVALUE(SUBSTITUTE(K33,CHAR(160),"")))/100 ) ) -> 0
B34: 2 | C34: =VLOOKUP(B34,Employees!A:B,2,FALSE) -> Umesh Kumar | D34: 0.83333333 | G34: 0.33333333 | H34: =F34 - E34 -> 0 | I34: =G34 - D34 -> -0.5 | J34: =I34 - H34 -> -0.5 | K34: =MAX( 0, MOD( IFERROR( J34, TIMEVALUE(SUBSTITUTE(J34,CHAR(160),"")) ), 1 ) - TIME(11,0,0) ) -> 0.041666667 | L34: =IF(J34="","", IFERROR( HOUR(MIN(MOD(J34,1), TIME(11,0,0))) + MINUTE(MIN(MOD(J34,1), TIME(11,0,0)))/100, HOUR(MIN(MOD(TIMEVALUE(SUBSTITUTE(J34,CHAR(160),"")),1), TIME(11,0,0))) + MINUTE(MIN(MOD(TIMEVALUE(SUBSTITUTE(J34,CHAR(160),"")),1), TIME(11,0,0)))/100 ) ) -> 11 | M34: =IF(K34="","", IFERROR( HOUR(K34)+MINUTE(K34)/100, HOUR(TIMEVALUE(SUBSTITUTE(K34,CHAR(160),""))) +MINUTE(TIMEVALUE(SUBSTITUTE(K34,CHAR(160),"")))/100 ) ) -> 1
A35: 46067 | B35: 1 | C35: =VLOOKUP(B35,Employees!A:B,2,FALSE) -> Rajat Hela | D35: 0.33333333 | E35: 0.54166667 | F35: 0.58333333 | G35: 0.83333333 | H35: =F35 - E35 -> 0.041666667 | I35: =G35 - D35 -> 0.5 | J35: =I35 - H35 -> 0.45833333 | K35: =MAX( 0, MOD( IFERROR( J35, TIMEVALUE(SUBSTITUTE(J35,CHAR(160),"")) ), 1 ) - TIME(11,0,0) ) -> 0 | L35: =IF(J35="","", IFERROR( HOUR(MIN(MOD(J35,1), TIME(11,0,0))) + MINUTE(MIN(MOD(J35,1), TIME(11,0,0)))/100, HOUR(MIN(MOD(TIMEVALUE(SUBSTITUTE(J35,CHAR(160),"")),1), TIME(11,0,0))) + MINUTE(MIN(MOD(TIMEVALUE(SUBSTITUTE(J35,CHAR(160),"")),1), TIME(11,0,0)))/100 ) ) -> 11 | M35: =IF(K35="","", IFERROR( HOUR(K35)+MINUTE(K35)/100, HOUR(TIMEVALUE(SUBSTITUTE(K35,CHAR(160),""))) +MINUTE(TIMEVALUE(SUBSTITUTE(K35,CHAR(160),"")))/100 ) ) -> 0
B36: 2 | C36: =VLOOKUP(B36,Employees!A:B,2,FALSE) -> Umesh Kumar | D36: 0.83333333 | G36: 0.33333333 | H36: =F36 - E36 -> 0 | I36: =G36 - D36 -> -0.5 | J36: =I36 - H36 -> -0.5 | K36: =MAX( 0, MOD( IFERROR( J36, TIMEVALUE(SUBSTITUTE(J36,CHAR(160),"")) ), 1 ) - TIME(11,0,0) ) -> 0.041666667 | L36: =IF(J36="","", IFERROR( HOUR(MIN(MOD(J36,1), TIME(11,0,0))) + MINUTE(MIN(MOD(J36,1), TIME(11,0,0)))/100, HOUR(MIN(MOD(TIMEVALUE(SUBSTITUTE(J36,CHAR(160),"")),1), TIME(11,0,0))) + MINUTE(MIN(MOD(TIMEVALUE(SUBSTITUTE(J36,CHAR(160),"")),1), TIME(11,0,0)))/100 ) ) -> 11 | M36: =IF(K36="","", IFERROR( HOUR(K36)+MINUTE(K36)/100, HOUR(TIMEVALUE(SUBSTITUTE(K36,CHAR(160),""))) +MINUTE(TIMEVALUE(SUBSTITUTE(K36,CHAR(160),"")))/100 ) ) -> 1
A37: 46068 | B37: 1 | C37: =VLOOKUP(B37,Employees!A:B,2,FALSE) -> Rajat Hela | D37: 0.33333333 | E37: 0.54166667 | F37: 0.58333333 | G37: 0.83333333 | H37: =F37 - E37 -> 0.041666667 | I37: =G37 - D37 -> 0.5 | J37: =I37 - H37 -> 0.45833333 | K37: =MAX( 0, MOD( IFERROR( J37, TIMEVALUE(SUBSTITUTE(J37,CHAR(160),"")) ), 1 ) - TIME(11,0,0) ) -> 0 | L37: =IF(J37="","", IFERROR( HOUR(MIN(MOD(J37,1), TIME(11,0,0))) + MINUTE(MIN(MOD(J37,1), TIME(11,0,0)))/100, HOUR(MIN(MOD(TIMEVALUE(SUBSTITUTE(J37,CHAR(160),"")),1), TIME(11,0,0))) + MINUTE(MIN(MOD(TIMEVALUE(SUBSTITUTE(J37,CHAR(160),"")),1), TIME(11,0,0)))/100 ) ) -> 11 | M37: =IF(K37="","", IFERROR( HOUR(K37)+MINUTE(K37)/100, HOUR(TIMEVALUE(SUBSTITUTE(K37,CHAR(160),""))) +MINUTE(TIMEVALUE(SUBSTITUTE(K37,CHAR(160),"")))/100 ) ) -> 0
B38: 2 | C38: =VLOOKUP(B38,Employees!A:B,2,FALSE) -> Umesh Kumar | D38: 0.83333333 | G38: 0.33333333 | H38: =F38 - E38 -> 0 | I38: =G38 - D38 -> -0.5 | J38: =I38 - H38 -> -0.5 | K38: =MAX( 0, MOD( IFERROR( J38, TIMEVALUE(SUBSTITUTE(J38,CHAR(160),"")) ), 1 ) - TIME(11,0,0) ) -> 0.041666667 | L38: =IF(J38="","", IFERROR( HOUR(MIN(MOD(J38,1), TIME(11,0,0))) + MINUTE(MIN(MOD(J38,1), TIME(11,0,0)))/100, HOUR(MIN(MOD(TIMEVALUE(SUBSTITUTE(J38,CHAR(160),"")),1), TIME(11,0,0))) + MINUTE(MIN(MOD(TIMEVALUE(SUBSTITUTE(J38,CHAR(160),"")),1), TIME(11,0,0)))/100 ) ) -> 11 | M38: =IF(K38="","", IFERROR( HOUR(K38)+MINUTE(K38)/100, HOUR(TIMEVALUE(SUBSTITUTE(K38,CHAR(160),""))) +MINUTE(TIMEVALUE(SUBSTITUTE(K38,CHAR(160),"")))/100 ) ) -> 1
A39: 46069 | B39: 1 | C39: =VLOOKUP(B39,Employees!A:B,2,FALSE) -> Rajat Hela | D39: 0.33333333 | E39: 0.54166667 | F39: 0.58333333 | G39: 0.83333333 | H39: =F39 - E39 -> 0.041666667 | I39: =G39 - D39 -> 0.5 | J39: =I39 - H39 -> 0.45833333 | K39: =MAX( 0, MOD( IFERROR( J39, TIMEVALUE(SUBSTITUTE(J39,CHAR(160),"")) ), 1 ) - TIME(11,0,0) ) -> 0 | L39: =IF(J39="","", IFERROR( HOUR(MIN(MOD(J39,1), TIME(11,0,0))) + MINUTE(MIN(MOD(J39,1), TIME(11,0,0)))/100, HOUR(MIN(MOD(TIMEVALUE(SUBSTITUTE(J39,CHAR(160),"")),1), TIME(11,0,0))) + MINUTE(MIN(MOD(TIMEVALUE(SUBSTITUTE(J39,CHAR(160),"")),1), TIME(11,0,0)))/100 ) ) -> 11 | M39: =IF(K39="","", IFERROR( HOUR(K39)+MINUTE(K39)/100, HOUR(TIMEVALUE(SUBSTITUTE(K39,CHAR(160),""))) +MINUTE(TIMEVALUE(SUBSTITUTE(K39,CHAR(160),"")))/100 ) ) -> 0
B40: 2 | C40: =VLOOKUP(B40,Employees!A:B,2,FALSE) -> Umesh Kumar | D40: 0.83333333 | G40: 0.33333333 | H40: =F40 - E40 -> 0 | I40: =G40 - D40 -> -0.5 | J40: =I40 - H40 -> -0.5 | K40: =MAX( 0, MOD( IFERROR( J40, TIMEVALUE(SUBSTITUTE(J40,CHAR(160),"")) ), 1 ) - TIME(11,0,0) ) -> 0.041666667 | L40: =IF(J40="","", IFERROR( HOUR(MIN(MOD(J40,1), TIME(11,0,0))) + MINUTE(MIN(MOD(J40,1), TIME(11,0,0)))/100, HOUR(MIN(MOD(TIMEVALUE(SUBSTITUTE(J40,CHAR(160),"")),1), TIME(11,0,0))) + MINUTE(MIN(MOD(TIMEVALUE(SUBSTITUTE(J40,CHAR(160),"")),1), TIME(11,0,0)))/100 ) ) -> 11 | M40: =IF(K40="","", IFERROR( HOUR(K40)+MINUTE(K40)/100, HOUR(TIMEVALUE(SUBSTITUTE(K40,CHAR(160),""))) +MINUTE(TIMEVALUE(SUBSTITUTE(K40,CHAR(160),"")))/100 ) ) -> 1
A41: 46070 | B41: 1 | C41: =VLOOKUP(B41,Employees!A:B,2,FALSE) -> Rajat Hela | D41: 0.33333333 | E41: 0.54166667 | F41: 0.58333333 | G41: 0.83333333 | H41: =F41 - E41 -> 0.041666667 | I41: =G41 - D41 -> 0.5 | J41: =I41 - H41 -> 0.45833333 | K41: =MAX( 0, MOD( IFERROR( J41, TIMEVALUE(SUBSTITUTE(J41,CHAR(160),"")) ), 1 ) - TIME(11,0,0) ) -> 0 | L41: =IF(J41="","", IFERROR( HOUR(MIN(MOD(J41,1), TIME(11,0,0))) + MINUTE(MIN(MOD(J41,1), TIME(11,0,0)))/100, HOUR(MIN(MOD(TIMEVALUE(SUBSTITUTE(J41,CHAR(160),"")),1), TIME(11,0,0))) + MINUTE(MIN(MOD(TIMEVALUE(SUBSTITUTE(J41,CHAR(160),"")),1), TIME(11,0,0)))/100 ) ) -> 11 | M41: =IF(K41="","", IFERROR( HOUR(K41)+MINUTE(K41)/100, HOUR(TIMEVALUE(SUBSTITUTE(K41,CHAR(160),""))) +MINUTE(TIMEVALUE(SUBSTITUTE(K41,CHAR(160),"")))/100 ) ) -> 0
B42: 2 | C42: =VLOOKUP(B42,Employees!A:B,2,FALSE) -> Umesh Kumar | D42: 0.83333333 | G42: 0.33333333 | H42: =F42 - E42 -> 0 | I42: =G42 - D42 -> -0.5 | J42: =I42 - H42 -> -0.5 | K42: =MAX( 0, MOD( IFERROR( J42, TIMEVALUE(SUBSTITUTE(J42,CHAR(160),"")) ), 1 ) - TIME(11,0,0) ) -> 0.041666667 | L42: =IF(J42="","", IFERROR( HOUR(MIN(MOD(J42,1), TIME(11,0,0))) + MINUTE(MIN(MOD(J42,1), TIME(11,0,0)))/100, HOUR(MIN(MOD(TIMEVALUE(SUBSTITUTE(J42,CHAR(160),"")),1), TIME(11,0,0))) + MINUTE(MIN(MOD(TIMEVALUE(SUBSTITUTE(J42,CHAR(160),"")),1), TIME(11,0,0)))/100 ) ) -> 11 | M42: =IF(K42="","", IFERROR( HOUR(K42)+MINUTE(K42)/100, HOUR(TIMEVALUE(SUBSTITUTE(K42,CHAR(160),""))) +MINUTE(TIMEVALUE(SUBSTITUTE(K42,CHAR(160),"")))/100 ) ) -> 1
A43: 46071 | B43: 2 | C43: =VLOOKUP(B43,Employees!A:B,2,FALSE) -> Umesh Kumar | D43: 0.33333333 | E43: 0.54166667 | F43: 0.072916667 | G43: 0.77083333 | H43: 0 | I43: 0.4375 | J43: 0.39583333 | K43: 0 | L43: =IF(J43="","", IFERROR( HOUR(MIN(MOD(J43,1), TIME(11,0,0))) + MINUTE(MIN(MOD(J43,1), TIME(11,0,0)))/100, HOUR(MIN(MOD(TIMEVALUE(SUBSTITUTE(J43,CHAR(160),"")),1), TIME(11,0,0))) + MINUTE(MIN(MOD(TIMEVALUE(SUBSTITUTE(J43,CHAR(160),"")),1), TIME(11,0,0)))/100 ) ) -> 9.3 | M43: =IF(K43="","", IFERROR( HOUR(K43)+MINUTE(K43)/100, HOUR(TIMEVALUE(SUBSTITUTE(K43,CHAR(160),""))) +MINUTE(TIMEVALUE(SUBSTITUTE(K43,CHAR(160),"")))/100 ) ) -> 0
A44: 46072 | B44: 2 | C44: =VLOOKUP(B44,Employees!A:B,2,FALSE) -> Umesh Kumar | D44: 0.33333333 | E44: 0.57291667 | F44: 0.61458333 | G44: 0.83333333 | H44: =F44 - E44 -> 0.041666667 | I44: =G44 - D44 -> 0.5 | J44: =I44 - H44 -> 0.45833333 | K44: =MAX( 0, MOD( IFERROR( J44, TIMEVALUE(SUBSTITUTE(J44,CHAR(160),"")) ), 1 ) - TIME(11,0,0) ) -> 0 | L44: =IF(J44="","", IFERROR( HOUR(MIN(MOD(J44,1), TIME(11,0,0))) + MINUTE(MIN(MOD(J44,1), TIME(11,0,0)))/100, HOUR(MIN(MOD(TIMEVALUE(SUBSTITUTE(J44,CHAR(160),"")),1), TIME(11,0,0))) + MINUTE(MIN(MOD(TIMEVALUE(SUBSTITUTE(J44,CHAR(160),"")),1), TIME(11,0,0)))/100 ) ) -> 11 | M44: =IF(K44="","", IFERROR( HOUR(K44)+MINUTE(K44)/100, HOUR(TIMEVALUE(SUBSTITUTE(K44,CHAR(160),""))) +MINUTE(TIMEVALUE(SUBSTITUTE(K44,CHAR(160),"")))/100 ) ) -> 0
...

Sheet 03-2026
A1: 46082
A5: Emp ID | B5: Employee Name | C5: Contact | D5: Department | E5: Designation | F5: Basic Salary | G5: Per Day Salary | H5: Per Hour Salary | I5: Total Hours | J5: Total OT (hrs) | K5: Salary Earned
A6: 1 | B6: =VLOOKUP(A6,Employees!A:B,2,FALSE) -> Rajat Hela | C6: =VLOOKUP(A6,Employees!A:C,3,FALSE) -> 9023270731 | D6: =VLOOKUP(A6,Employees!A:D,4,FALSE) -> Production | E6: =VLOOKUP(A6,Employees!A:E,5,FALSE) -> CNC Machine Operator | F6: =VLOOKUP(A6,Employees!A:F,6,FALSE) -> 17000 | G6: =VLOOKUP(A6,Employees!A:G,7,FALSE) -> 653.84615 | H6: =VLOOKUP(A6,Employees!A:H,8,FALSE) -> 59.440559 | I6: =SUMIFS('03-2026'!$L$10:$L$291, '03-2026'!$B$10:$B$291, $A6) -> 278.3 | J6: =SUMIFS('03-2026'!$M$10:$M$291, '03-2026'!$B$10:$B$291, $A6) -> 17 | K6: =('03-2026'!$I6+'03-2026'!$J6)*'03-2026'!$H6 -> 17552.797
A7: 2 | B7: =VLOOKUP(A7,Employees!A:B,2,FALSE) -> Umesh Kumar | C7: =VLOOKUP(A7,Employees!A:C,3,FALSE) | D7: =VLOOKUP(A7,Employees!A:D,4,FALSE) -> Production | E7: =VLOOKUP(A7,Employees!A:E,5,FALSE) -> CNC Machine Operator | F7: 18000 | G7: =VLOOKUP(A7,Employees!A:G,7,FALSE) -> 692.30769 | H7: =VLOOKUP(A7,Employees!A:H,8,FALSE) -> 62.937063 | I7: =SUMIFS('03-2026'!$L$10:$L$291, '03-2026'!$B$10:$B$291, $A7) -> 261.4 | J7: =SUMIFS('03-2026'!$M$10:$M$291, '03-2026'!$B$10:$B$291, $A7) -> 9.9 | K7: =('03-2026'!$I7+'03-2026'!$J7)*'03-2026'!$H7 -> 17074.825
